Workbook

Sheet H743xIG Pins
A1: # | B1: Name/Function | C1: AF (Core Board) | D1: Conn. Pin | E1: AF (Mission Board Opt. 1) | F1: AF (Mission Board Opt. 2) | G1: ADC | H1: Use/Notes | I1: SPI | J1: FDCAN | K1: ETH | L1: Timers | M1: USB (OTG) | N1: UART | O1: DAC | P1: Other | Q1: Additional functions | R1: Alternate functions | S1: https://www.st.com/resource/en/datasheet/stm32h743bi.pdf
A2: 94 | B2: BOOT0 | D2: =IF(COUNTIF(ConnectorPins!$F$2:$F$999, B2) > 0, MATCH(B2, ConnectorPins!$F$2:$F$999, 0), IF(COUNTIF(ConnectorPins!$I$2:$I$999, B2) > 0, MATCH(B2, ConnectorPins!$I$2:$I$999, 0), "")) | G2: =IFERROR(__xludf.DUMMYFUNCTION("TRIM(REGEXREPLACE(Q2 , ""ADC(._[A-Z0-9]*)|."" , ""$1 "") )"),"") | I2: =IFERROR(__xludf.DUMMYFUNCTION("TRIM(REGEXREPLACE(R2 , ""SPI(._(MOSI|MISO|SCK))|."" , ""$1 "") )"),"") | J2: =IFERROR(__xludf.DUMMYFUNCTION("TRIM(REGEXREPLACE(R2 , ""FDCAN(._[\w_]+)|."" , ""$1 "") )"),"") | K2: =IFERROR(__xludf.DUMMYFUNCTION("TRIM(REGEXREPLACE(R2 , ""ETH_([\w_]+)|."" , ""$1 "") )"),"") | L2: =IFERROR(__xludf.DUMMYFUNCTION("TRIM(REGEXREPLACE(R2 , ""TIM(._\w+)|."" , ""$1 "") )"),"") | M2: =IFERROR(__xludf.DUMMYFUNCTION("TRIM(REGEXREPLACE(R2 , ""OTG_([\w_]+)|."" , ""$1 "") )"),"") | N2: =IFERROR(__xludf.DUMMYFUNCTION("TRIM(REGEXREPLACE(R2 , ""US?ART(._(TX|RX))|."" , ""$1 "") )"),"") | O2: =IFERROR(__xludf.DUMMYFUNCTION("TRIM(REGEXREPLACE(Q2 , ""DAC(\d+_OUT\d+)|."" , ""$1 "") )"),"") | P2: =IFERROR(__xludf.DUMMYFUNCTION("TRIM(REGEXREPLACE(REGEXREPLACE(R2, "","", "" ""), ""(EVENTOUT|TRACECLK|TRACED.|SPI._[^ ]*|SAI._[^ ]*|ETH_[^ ]*|QUADSPI_[^ ]*|FMC_[^ ]*|UART._[^ ]*|FDCAN._[^ ]*|DFSDM._[^ ]*|OTG_[^ ]*|TIM\d+_[^ ]*)( |$)"", "" ""))"),"") | Q2: VPP
A3: 14 | B3: NRST | D3: =IF(COUNTIF(ConnectorPins!$F$2:$F$999, B3) > 0, MATCH(B3, ConnectorPins!$F$2:$F$999, 0), IF(COUNTIF(ConnectorPins!$I$2:$I$999, B3) > 0, MATCH(B3, ConnectorPins!$I$2:$I$999, 0) + 35, "")) | G3: =IFERROR(__xludf.DUMMYFUNCTION("TRIM(REGEXREPLACE(Q3 , ""ADC(._[A-Z0-9]*)|."" , ""$1 "") )"),"") | I3: =IFERROR(__xludf.DUMMYFUNCTION("TRIM(REGEXREPLACE(R3 , ""SPI(._(MOSI|MISO|SCK))|."" , ""$1 "") )"),"") | J3: =IFERROR(__xludf.DUMMYFUNCTION("TRIM(REGEXREPLACE(R3 , ""FDCAN(._[\w_]+)|."" , ""$1 "") )"),"") | K3: =IFERROR(__xludf.DUMMYFUNCTION("TRIM(REGEXREPLACE(R3 , ""ETH_([\w_]+)|."" , ""$1 "") )"),"") | L3: =IFERROR(__xludf.DUMMYFUNCTION("TRIM(REGEXREPLACE(R3 , ""TIM(._\w+)|."" , ""$1 "") )"),"") | M3: =IFERROR(__xludf.DUMMYFUNCTION("TRIM(REGEXREPLACE(R3 , ""OTG_([\w_]+)|."" , ""$1 "") )"),"") | N3: =IFERROR(__xludf.DUMMYFUNCTION("TRIM(REGEXREPLACE(R3 , ""US?ART(._(TX|RX))|."" , ""$1 "") )"),"") | O3: =IFERROR(__xludf.DUMMYFUNCTION("TRIM(REGEXREPLACE(Q3 , ""DAC(\d+_OUT\d+)|."" , ""$1 "") )"),"") | P3: =IFERROR(__xludf.DUMMYFUNCTION("TRIM(REGEXREPLACE(REGEXREPLACE(R3, "","", "" ""), ""(EVENTOUT|TRACECLK|TRACED.|SPI._[^ ]*|SAI._[^ ]*|ETH_[^ ]*|QUADSPI_[^ ]*|FMC_[^ ]*|UART._[^ ]*|FDCAN._[^ ]*|DFSDM._[^ ]*|OTG_[^ ]*|TIM\d+_[^ ]*)( |$)"", "" ""))"),"")
A4: 22 | B4: PA0 | D4: =IF(COUNTIF(ConnectorPins!$F$2:$F$999, B4) > 0, MATCH(B4, ConnectorPins!$F$2:$F$999, 0), IF(COUNTIF(ConnectorPins!$I$2:$I$999, B4) > 0, MATCH(B4, ConnectorPins!$I$2:$I$999, 0) + 35, "")) -> 59 | F4: UART4_TX | G4: =IFERROR(__xludf.DUMMYFUNCTION("TRIM(REGEXREPLACE(Q4 , ""ADC(\d+_(INN\d+|INP\d+)*)|."" , ""$1 "") )"),"1_INP16") -> 1_INP16 | I4: =IFERROR(__xludf.DUMMYFUNCTION("TRIM(REGEXREPLACE(R4 , ""SPI(._(MOSI|MISO|SCK))|."" , ""$1 "") )"),"") | J4: =IFERROR(__xludf.DUMMYFUNCTION("TRIM(REGEXREPLACE(R4 , ""FDCAN(._[\w_]+)|."" , ""$1 "") )"),"") | K4: =IFERROR(__xludf.DUMMYFUNCTION("TRIM(REGEXREPLACE(R4 , ""ETH_([\w_]+)|."" , ""$1 "") )"),"MII_CRS") -> MII_CRS | L4: =IFERROR(__xludf.DUMMYFUNCTION("TRIM(REGEXREPLACE(R4 , ""TIM(._\w+)|."" , ""$1 "") )"),"2_CH1 2_ETR 5_CH1 8_ETR") -> 2_CH1 2_ETR 5_CH1 8_ETR | M4: =IFERROR(__xludf.DUMMYFUNCTION("TRIM(REGEXREPLACE(R4 , ""OTG_([\w_]+)|."" , ""$1 "") )"),"") | N4: =IFERROR(__xludf.DUMMYFUNCTION("TRIM(REGEXREPLACE(R4 , ""US?ART(._(TX|RX))|."" , ""$1 "") )"),"4_TX") -> 4_TX | O4: =IFERROR(__xludf.DUMMYFUNCTION("TRIM(REGEXREPLACE(Q4 , ""DAC(\d+_OUT\d+)|."" , ""$1 "") )"),"") | P4: =IFERROR(__xludf.DUMMYFUNCTION("TRIM(REGEXREPLACE(REGEXREPLACE(R4, "","", "" ""), ""(EVENTOUT|TRACECLK|TRACED.|SPI._[^ ]*|SAI._[^ ]*|ETH_[^ ]*|QUADSPI_[^ ]*|FMC_[^ ]*|UART._[^ ]*|FDCAN._[^ ]*|DFSDM._[^ ]*|OTG_[^ ]*|TIM\d+_[^ ]*)( |$)"", "" ""))"),"USART2_CTS/USART2_NSS SDMMC2_CMD") -> USART2_CTS/USART2_NSS SDMMC2_CMD | Q4: ADC1_INP16,WKUP1 | R4: TIM2_CH1/TIM2_ETR,TIM5_CH1, TIM8_ETR,TIM15_BKIN,USART2_CTS/USART2_NSS, UART4_TX,SDMMC2_CMD,SAI2_SD_B,ETH_MII_CRS,EVENTOUT
A5: 23 | B5: PA1 | D5: =IF(COUNTIF(ConnectorPins!$F$2:$F$999, B5) > 0, MATCH(B5, ConnectorPins!$F$2:$F$999, 0), IF(COUNTIF(ConnectorPins!$I$2:$I$999, B5) > 0, MATCH(B5, ConnectorPins!$I$2:$I$999, 0) + 35, "")) -> 60 | E5: ETH_RMII_REF_CLK | F5: UART4_RX | G5: =IFERROR(__xludf.DUMMYFUNCTION("TRIM(REGEXREPLACE(Q5 , ""ADC(\d+_(INN\d+|INP\d+)*)|."" , ""$1 "") )"),"1_INN16 1_INP17") -> 1_INN16 1_INP17 | I5: =IFERROR(__xludf.DUMMYFUNCTION("TRIM(REGEXREPLACE(R5 , ""SPI(._(MOSI|MISO|SCK))|."" , ""$1 "") )"),"") | J5: =IFERROR(__xludf.DUMMYFUNCTION("TRIM(REGEXREPLACE(R5 , ""FDCAN(._[\w_]+)|."" , ""$1 "") )"),"") | K5: =IFERROR(__xludf.DUMMYFUNCTION("TRIM(REGEXREPLACE(R5 , ""ETH_([\w_]+)|."" , ""$1 "") )"),"MII_RX_CLK RMII_REF_CLK") -> MII_RX_CLK RMII_REF_CLK | L5: =IFERROR(__xludf.DUMMYFUNCTION("TRIM(REGEXREPLACE(R5 , ""TIM(._\w+)|."" , ""$1 "") )"),"2_CH2 5_CH2 3_OUT") -> 2_CH2 5_CH2 3_OUT | M5: =IFERROR(__xludf.DUMMYFUNCTION("TRIM(REGEXREPLACE(R5 , ""OTG_([\w_]+)|."" , ""$1 "") )"),"") | N5: =IFERROR(__xludf.DUMMYFUNCTION("TRIM(REGEXREPLACE(R5 , ""US?ART(._(TX|RX))|."" , ""$1 "") )"),"4_RX") -> 4_RX | O5: =IFERROR(__xludf.DUMMYFUNCTION("TRIM(REGEXREPLACE(Q5 , ""DAC(\d+_OUT\d+)|."" , ""$1 "") )"),"") | P5: =IFERROR(__xludf.DUMMYFUNCTION("TRIM(REGEXREPLACE(REGEXREPLACE(R5, "","", "" ""), ""(EVENTOUT|TRACECLK|TRACED.|SPI._[^ ]*|SAI._[^ ]*|ETH_[^ ]*|QUADSPI_[^ ]*|FMC_[^ ]*|UART._[^ ]*|FDCAN._[^ ]*|DFSDM._[^ ]*|OTG_[^ ]*|TIM\d+_[^ ]*)( |$)"", "" ""))"),"LP USART2_RTS/USART2_DE LCD_R2") -> LP USART2_RTS/USART2_DE LCD_R2 | Q5: ADC1_INN16,ADC1_INP17 | R5: TIM2_CH2, TIM5_CH2,LPTIM3_OUT,TIM15_CH1N,USART2_RTS/USART2_DE, UART4_RX,QUADSPI_BK1_IO3,SAI2_MCLK_B,ETH_MII_RX_CLK/ETH_RMII_REF_CLK,LCD_R2, EVENTOUT
A6: 69 | B6: PA10 | C6: Output/Timer | D6: =IF(COUNTIF(ConnectorPins!$F$2:$F$999, B6) > 0, MATCH(B6, ConnectorPins!$F$2:$F$999, 0), IF(COUNTIF(ConnectorPins!$I$2:$I$999, B6) > 0, MATCH(B6, ConnectorPins!$I$2:$I$999, 0), "")) | G6: =IFERROR(__xludf.DUMMYFUNCTION("TRIM(REGEXREPLACE(Q6 , ""ADC(\d+_(INN\d+|INP\d+)*)|."" , ""$1 "") )"),"") | H6: LED | I6: =IFERROR(__xludf.DUMMYFUNCTION("TRIM(REGEXREPLACE(R6 , ""SPI(._(MOSI|MISO|SCK))|."" , ""$1 "") )"),"") | J6: =IFERROR(__xludf.DUMMYFUNCTION("TRIM(REGEXREPLACE(R6 , ""FDCAN(._[\w_]+)|."" , ""$1 "") )"),"") | K6: =IFERROR(__xludf.DUMMYFUNCTION("TRIM(REGEXREPLACE(R6 , ""ETH_([\w_]+)|."" , ""$1 "") )"),"") | L6: =IFERROR(__xludf.DUMMYFUNCTION("TRIM(REGEXREPLACE(R6 , ""TIM(._\w+)|."" , ""$1 "") )"),"1_CH3") -> 1_CH3 | M6: =IFERROR(__xludf.DUMMYFUNCTION("TRIM(REGEXREPLACE(R6 , ""OTG_([\w_]+)|."" , ""$1 "") )"),"FS_ID") -> FS_ID | N6: =IFERROR(__xludf.DUMMYFUNCTION("TRIM(REGEXREPLACE(R6 , ""US?ART(._(TX|RX))|."" , ""$1 "") )"),"1_RX 1_RX") -> 1_RX 1_RX | O6: =IFERROR(__xludf.DUMMYFUNCTION("TRIM(REGEXREPLACE(Q6 , ""DAC(\d+_OUT\d+)|."" , ""$1 "") )"),"") | P6: =IFERROR(__xludf.DUMMYFUNCTION("TRIM(REGEXREPLACE(REGEXREPLACE(R6, "","", "" ""), ""(EVENTOUT|TRACECLK|TRACED.|SPI._[^ ]*|SAI._[^ ]*|ETH_[^ ]*|QUADSPI_[^ ]*|FMC_[^ ]*|UART._[^ ]*|FDCAN._[^ ]*|DFSDM._[^ ]*|OTG_[^ ]*|TIM\d+_[^ ]*)( |$)"", "" ""))"),"HRTIM_CHC2 LP USART1_RX MDIOS_MDIO LCD_B4 DCMI_D1 LCD_B1") -> HRTIM_CHC2 LP USART1_RX MDIOS_MDIO LCD_B4 DCMI_D1 LCD_B1 | R6: TIM1_CH3,HRTIM_CHC2,LPUART1_RX,USART1_RX,OTG_FS_ID,MDIOS_MDIO, LCD_B4,DCMI_D1, LCD_B1,EVENTOUT
A7: 70 | B7: PA11 | C7: OTG_FS_DM | D7: =IF(COUNTIF(ConnectorPins!$F$2:$F$999, B7) > 0, MATCH(B7, ConnectorPins!$F$2:$F$999, 0), IF(COUNTIF(ConnectorPins!$I$2:$I$999, B7) > 0, MATCH(B7, ConnectorPins!$I$2:$I$999, 0), "")) | G7: =IFERROR(__xludf.DUMMYFUNCTION("TRIM(REGEXREPLACE(Q7 , ""ADC(\d+_(INN\d+|INP\d+)*)|."" , ""$1 "") )"),"") | I7: =IFERROR(__xludf.DUMMYFUNCTION("TRIM(REGEXREPLACE(R7 , ""SPI(._(MOSI|MISO|SCK))|."" , ""$1 "") )"),"") | J7: =IFERROR(__xludf.DUMMYFUNCTION("TRIM(REGEXREPLACE(R7 , ""FDCAN(._[\w_]+)|."" , ""$1 "") )"),"1_RX") -> 1_RX | K7: =IFERROR(__xludf.DUMMYFUNCTION("TRIM(REGEXREPLACE(R7 , ""ETH_([\w_]+)|."" , ""$1 "") )"),"") | L7: =IFERROR(__xludf.DUMMYFUNCTION("TRIM(REGEXREPLACE(R7 , ""TIM(._\w+)|."" , ""$1 "") )"),"1_CH4") -> 1_CH4 | M7: =IFERROR(__xludf.DUMMYFUNCTION("TRIM(REGEXREPLACE(R7 , ""OTG_([\w_]+)|."" , ""$1 "") )"),"FS_DM") -> FS_DM | N7: =IFERROR(__xludf.DUMMYFUNCTION("TRIM(REGEXREPLACE(R7 , ""US?ART(._(TX|RX))|."" , ""$1 "") )"),"4_RX") -> 4_RX | O7: =IFERROR(__xludf.DUMMYFUNCTION("TRIM(REGEXREPLACE(Q7 , ""DAC(\d+_OUT\d+)|."" , ""$1 "") )"),"") | P7: =IFERROR(__xludf.DUMMYFUNCTION("TRIM(REGEXREPLACE(REGEXREPLACE(R7, "","", "" ""), ""(EVENTOUT|TRACECLK|TRACED.|SPI._[^ ]*|SAI._[^ ]*|ETH_[^ ]*|QUADSPI_[^ ]*|FMC_[^ ]*|UART._[^ ]*|FDCAN._[^ ]*|DFSDM._[^ ]*|OTG_[^ ]*|TIM\d+_[^ ]*)( |$)"", "" ""))"),"HRTIM_CHD1 LP USART1_CTS/USART1_NSS LCD_R4") -> HRTIM_CHD1 LP USART1_CTS/USART1_NSS LCD_R4 | R7: TIM1_CH4,HRTIM_CHD1,LPUART1_CTS,SPI2_NSS/I2S2_WS,UART4_RX,USART1_CTS/USART1_NSS, FDCAN1_RX,OTG_FS_DM, LCD_R4,EVENTOUT
A8: 71 | B8: PA12 | C8: OTG_FS_DP | D8: =IF(COUNTIF(ConnectorPins!$F$2:$F$999, B8) > 0, MATCH(B8, ConnectorPins!$F$2:$F$999, 0), IF(COUNTIF(ConnectorPins!$I$2:$I$999, B8) > 0, MATCH(B8, ConnectorPins!$I$2:$I$999, 0), "")) | G8: =IFERROR(__xludf.DUMMYFUNCTION("TRIM(REGEXREPLACE(Q8 , ""ADC(\d+_(INN\d+|INP\d+)*)|."" , ""$1 "") )"),"") | I8: =IFERROR(__xludf.DUMMYFUNCTION("TRIM(REGEXREPLACE(R8 , ""SPI(._(MOSI|MISO|SCK))|."" , ""$1 "") )"),"2_SCK") -> 2_SCK | J8: =IFERROR(__xludf.DUMMYFUNCTION("TRIM(REGEXREPLACE(R8 , ""FDCAN(._[\w_]+)|."" , ""$1 "") )"),"1_TX") -> 1_TX | K8: =IFERROR(__xludf.DUMMYFUNCTION("TRIM(REGEXREPLACE(R8 , ""ETH_([\w_]+)|."" , ""$1 "") )"),"") | L8: =IFERROR(__xludf.DUMMYFUNCTION("TRIM(REGEXREPLACE(R8 , ""TIM(._\w+)|."" , ""$1 "") )"),"1_ETR") -> 1_ETR | M8: =IFERROR(__xludf.DUMMYFUNCTION("TRIM(REGEXREPLACE(R8 , ""OTG_([\w_]+)|."" , ""$1 "") )"),"FS_DP") -> FS_DP | N8: =IFERROR(__xludf.DUMMYFUNCTION("TRIM(REGEXREPLACE(R8 , ""US?ART(._(TX|RX))|."" , ""$1 "") )"),"4_TX") -> 4_TX | O8: =IFERROR(__xludf.DUMMYFUNCTION("TRIM(REGEXREPLACE(Q8 , ""DAC(\d+_OUT\d+)|."" , ""$1 "") )"),"") | P8: =IFERROR(__xludf.DUMMYFUNCTION("TRIM(REGEXREPLACE(REGEXREPLACE(R8, "","", "" ""), ""(EVENTOUT|TRACECLK|TRACED.|SPI._[^ ]*|SAI._[^ ]*|ETH_[^ ]*|QUADSPI_[^ ]*|FMC_[^ ]*|UART._[^ ]*|FDCAN._[^ ]*|DFSDM._[^ ]*|OTG_[^ ]*|TIM\d+_[^ ]*)( |$)"", "" ""))"),"HRTIM_CHD2 LP USART1_RTS/USART1_DE LCD_R5") -> HRTIM_CHD2 LP USART1_RTS/USART1_DE LCD_R5 | R8: TIM1_ETR,HRTIM_CHD2,LPUART1_RTS/LPUART1_DE,SPI2_SCK/I2S2_CK,UART4_TX,USART1_RTS/USART1_DE, SAI2_FS_B,FDCAN1_TX,OTG_FS_DP, LCD_R5,EVENTOUT
A9: 72 | B9: PA13(JTMS/SWDIO) | D9: =IF(COUNTIF(ConnectorPins!$F$2:$F$999, B9) > 0, MATCH(B9, ConnectorPins!$F$2:$F$999, 0), IF(COUNTIF(ConnectorPins!$I$2:$I$999, B9) > 0, MATCH(B9, ConnectorPins!$I$2:$I$999, 0), "")) | G9: =IFERROR(__xludf.DUMMYFUNCTION("TRIM(REGEXREPLACE(Q9 , ""ADC(\d+_(INN\d+|INP\d+)*)|."" , ""$1 "") )"),"") | I9: =IFERROR(__xludf.DUMMYFUNCTION("TRIM(REGEXREPLACE(R9 , ""SPI(._(MOSI|MISO|SCK))|."" , ""$1 "") )"),"") | J9: =IFERROR(__xludf.DUMMYFUNCTION("TRIM(REGEXREPLACE(R9 , ""FDCAN(._[\w_]+)|."" , ""$1 "") )"),"") | K9: =IFERROR(__xludf.DUMMYFUNCTION("TRIM(REGEXREPLACE(R9 , ""ETH_([\w_]+)|."" , ""$1 "") )"),"") | L9: =IFERROR(__xludf.DUMMYFUNCTION("TRIM(REGEXREPLACE(R9 , ""TIM(._\w+)|."" , ""$1 "") )"),"") | M9: =IFERROR(__xludf.DUMMYFUNCTION("TRIM(REGEXREPLACE(R9 , ""OTG_([\w_]+)|."" , ""$1 "") )"),"") | N9: =IFERROR(__xludf.DUMMYFUNCTION("TRIM(REGEXREPLACE(R9 , ""US?ART(._(TX|RX))|."" , ""$1 "") )"),"") | O9: =IFERROR(__xludf.DUMMYFUNCTION("TRIM(REGEXREPLACE(Q9 , ""DAC(\d+_OUT\d+)|."" , ""$1 "") )"),"") | P9: =IFERROR(__xludf.DUMMYFUNCTION("TRIM(REGEXREPLACE(REGEXREPLACE(R9, "","", "" ""), ""(EVENTOUT|TRACECLK|TRACED.|SPI._[^ ]*|SAI._[^ ]*|ETH_[^ ]*|QUADSPI_[^ ]*|FMC_[^ ]*|UART._[^ ]*|FDCAN._[^ ]*|DFSDM._[^ ]*|OTG_[^ ]*|TIM\d+_[^ ]*)( |$)"", "" ""))"),"JTMS-SWDIO") -> JTMS-SWDIO | R9: JTMS-SWDIO,EVENTOUT
A10: 76 | B10: PA14(JTCK/SWCLK) | D10: =IF(COUNTIF(ConnectorPins!$F$2:$F$999, B10) > 0, MATCH(B10, ConnectorPins!$F$2:$F$999, 0), IF(COUNTIF(ConnectorPins!$I$2:$I$999, B10) > 0, MATCH(B10, ConnectorPins!$I$2:$I$999, 0), "")) | G10: =IFERROR(__xludf.DUMMYFUNCTION("TRIM(REGEXREPLACE(Q10 , ""ADC(\d+_(INN\d+|INP\d+)*)|."" , ""$1 "") )"),"") | I10: =IFERROR(__xludf.DUMMYFUNCTION("TRIM(REGEXREPLACE(R10 , ""SPI(._(MOSI|MISO|SCK))|."" , ""$1 "") )"),"") | J10: =IFERROR(__xludf.DUMMYFUNCTION("TRIM(REGEXREPLACE(R10 , ""FDCAN(._[\w_]+)|."" , ""$1 "") )"),"") | K10: =IFERROR(__xludf.DUMMYFUNCTION("TRIM(REGEXREPLACE(R10 , ""ETH_([\w_]+)|."" , ""$1 "") )"),"") | L10: =IFERROR(__xludf.DUMMYFUNCTION("TRIM(REGEXREPLACE(R10 , ""TIM(._\w+)|."" , ""$1 "") )"),"") | M10: =IFERROR(__xludf.DUMMYFUNCTION("TRIM(REGEXREPLACE(R10 , ""OTG_([\w_]+)|."" , ""$1 "") )"),"") | N10: =IFERROR(__xludf.DUMMYFUNCTION("TRIM(REGEXREPLACE(R10 , ""US?ART(._(TX|RX))|."" , ""$1 "") )"),"") | O10: =IFERROR(__xludf.DUMMYFUNCTION("TRIM(REGEXREPLACE(Q10 , ""DAC(\d+_OUT\d+)|."" , ""$1 "") )"),"") | P10: =IFERROR(__xludf.DUMMYFUNCTION("TRIM(REGEXREPLACE(REGEXREPLACE(R10, "","", "" ""), ""(EVENTOUT|TRACECLK|TRACED.|SPI._[^ ]*|SAI._[^ ]*|ETH_[^ ]*|QUADSPI_[^ ]*|FMC_[^ ]*|UART._[^ ]*|FDCAN._[^ ]*|DFSDM._[^ ]*|OTG_[^ ]*|TIM\d+_[^ ]*)( |$)"", "" ""))"),"JTCK-SWCLK") -> JTCK-SWCLK | R10: JTCK-SWCLK,EVENTOUT
A11: 77 | B11: PA15(JTDI) | C11: Output/Timer | D11: =IF(COUNTIF(ConnectorPins!$F$2:$F$999, B11) > 0, MATCH(B11, ConnectorPins!$F$2:$F$999, 0), IF(COUNTIF(ConnectorPins!$I$2:$I$999, B11) > 0, MATCH(B11, ConnectorPins!$I$2:$I$999, 0), "")) | G11: =IFERROR(__xludf.DUMMYFUNCTION("TRIM(REGEXREPLACE(Q11 , ""ADC(\d+_(INN\d+|INP\d+)*)|."" , ""$1 "") )"),"") | H11: LED | I11: =IFERROR(__xludf.DUMMYFUNCTION("TRIM(REGEXREPLACE(R11 , ""SPI(._(MOSI|MISO|SCK))|."" , ""$1 "") )"),"") | J11: =IFERROR(__xludf.DUMMYFUNCTION("TRIM(REGEXREPLACE(R11 , ""FDCAN(._[\w_]+)|."" , ""$1 "") )"),"") | K11: =IFERROR(__xludf.DUMMYFUNCTION("TRIM(REGEXREPLACE(R11 , ""ETH_([\w_]+)|."" , ""$1 "") )"),"") | L11: =IFERROR(__xludf.DUMMYFUNCTION("TRIM(REGEXREPLACE(R11 , ""TIM(._\w+)|."" , ""$1 "") )"),"2_CH1 2_ETR") -> 2_CH1 2_ETR | M11: =IFERROR(__xludf.DUMMYFUNCTION("TRIM(REGEXREPLACE(R11 , ""OTG_([\w_]+)|."" , ""$1 "") )"),"") | N11: =IFERROR(__xludf.DUMMYFUNCTION("TRIM(REGEXREPLACE(R11 , ""US?ART(._(TX|RX))|."" , ""$1 "") )"),"7_TX") -> 7_TX | O11: =IFERROR(__xludf.DUMMYFUNCTION("TRIM(REGEXREPLACE(Q11 , ""DAC(\d+_OUT\d+)|."" , ""$1 "") )"),"") | P11: =IFERROR(__xludf.DUMMYFUNCTION("TRIM(REGEXREPLACE(REGEXREPLACE(R11, "","", "" ""), ""(EVENTOUT|TRACECLK|TRACED.|SPI._[^ ]*|SAI._[^ ]*|ETH_[^ ]*|QUADSPI_[^ ]*|FMC_[^ ]*|UART._[^ ]*|FDCAN._[^ ]*|DFSDM._[^ ]*|OTG_[^ ]*|TIM\d+_[^ ]*)( |$)"", "" ""))"),"JTDI HRTIM_FLT1 CEC") -> JTDI HRTIM_FLT1 CEC | R11: JTDI,TIM2_CH1/TIM2_ETR,HRTIM_FLT1, CEC,SPI1_NSS/I2S1_WS,SPI3_NSS/I2S3_WS,SPI6_NSS,UART4_RTS/UART4_DE, UART7_TX,EVENTOUT
A12: 24 | B12: PA2 | D12: =IF(COUNTIF(ConnectorPins!$F$2:$F$999, B12) > 0, MATCH(B12, ConnectorPins!$F$2:$F$999, 0), IF(COUNTIF(ConnectorPins!$I$2:$I$999, B12) > 0, MATCH(B12, ConnectorPins!$I$2:$I$999, 0) + 35, "")) -> 61 | E12: ETH_MDIO | F12: UART2_TX | G12: =IFERROR(__xludf.DUMMYFUNCTION("TRIM(REGEXREPLACE(Q12 , ""ADC(\d+_(INN\d+|INP\d+)*)|."" , ""$1 "") )"),"12_INP14") -> 12_INP14 | I12: =IFERROR(__xludf.DUMMYFUNCTION("TRIM(REGEXREPLACE(R12 , ""SPI(._(MOSI|MISO|SCK))|."" , ""$1 "") )"),"") | J12: =IFERROR(__xludf.DUMMYFUNCTION("TRIM(REGEXREPLACE(R12 , ""FDCAN(._[\w_]+)|."" , ""$1 "") )"),"") | K12: =IFERROR(__xludf.DUMMYFUNCTION("TRIM(REGEXREPLACE(R12 , ""ETH_([\w_]+)|."" , ""$1 "") )"),"MDIO") -> MDIO | L12: =IFERROR(__xludf.DUMMYFUNCTION("TRIM(REGEXREPLACE(R12 , ""TIM(._\w+)|."" , ""$1 "") )"),"2_CH3 5_CH3 4_OUT") -> 2_CH3 5_CH3 4_OUT | M12: =IFERROR(__xludf.DUMMYFUNCTION("TRIM(REGEXREPLACE(R12 , ""OTG_([\w_]+)|."" , ""$1 "") )"),"") | N12: =IFERROR(__xludf.DUMMYFUNCTION("TRIM(REGEXREPLACE(R12 , ""US?ART(._(TX|RX))|."" , ""$1 "") )"),"2_TX") -> 2_TX | O12: =IFERROR(__xludf.DUMMYFUNCTION("TRIM(REGEXREPLACE(Q12 , ""DAC(\d+_OUT\d+)|."" , ""$1 "") )"),"") | P12: =IFERROR(__xludf.DUMMYFUNCTION("TRIM(REGEXREPLACE(REGEXREPLACE(R12, "","", "" ""), ""(EVENTOUT|TRACECLK|TRACED.|SPI._[^ ]*|SAI._[^ ]*|ETH_[^ ]*|QUADSPI_[^ ]*|FMC_[^ ]*|UART._[^ ]*|FDCAN._[^ ]*|DFSDM._[^ ]*|OTG_[^ ]*|TIM\d+_[^ ]*)( |$)"", "" ""))"),"LP USART2_TX MDIOS_MDIO LCD_R1") -> LP USART2_TX MDIOS_MDIO LCD_R1 | Q12: ADC12_INP14,WKUP2 | R12: TIM2_CH3, TIM5_CH3,LPTIM4_OUT,TIM15_CH1,USART2_TX,SAI2_SCK_B,ETH_MDIO,MDIOS_MDIO, LCD_R1,EVENTOUT
A13: 25 | B13: PA3 | D13: =IF(COUNTIF(ConnectorPins!$F$2:$F$999, B13) > 0, MATCH(B13, ConnectorPins!$F$2:$F$999, 0), IF(COUNTIF(ConnectorPins!$I$2:$I$999, B13) > 0, MATCH(B13, ConnectorPins!$I$2:$I$999, 0) + 35, "")) -> 62 | E13: ADC12_INP15 | F13: UART2_RX | G13: =IFERROR(__xludf.DUMMYFUNCTION("TRIM(REGEXREPLACE(Q13 , ""ADC(\d+_(INN\d+|INP\d+)*)|."" , ""$1 "") )"),"12_INP15") -> 12_INP15 | I13: =IFERROR(__xludf.DUMMYFUNCTION("TRIM(REGEXREPLACE(R13 , ""SPI(._(MOSI|MISO|SCK))|."" , ""$1 "") )"),"") | J13: =IFERROR(__xludf.DUMMYFUNCTION("TRIM(REGEXREPLACE(R13 , ""FDCAN(._[\w_]+)|."" , ""$1 "") )"),"") | K13: =IFERROR(__xludf.DUMMYFUNCTION("TRIM(REGEXREPLACE(R13 , ""ETH_([\w_]+)|."" , ""$1 "") )"),"MII_COL") -> MII_COL | L13: =IFERROR(__xludf.DUMMYFUNCTION("TRIM(REGEXREPLACE(R13 , ""TIM(._\w+)|."" , ""$1 "") )"),"2_CH4 5_CH4 5_OUT") -> 2_CH4 5_CH4 5_OUT | M13: =IFERROR(__xludf.DUMMYFUNCTION("TRIM(REGEXREPLACE(R13 , ""OTG_([\w_]+)|."" , ""$1 "") )"),"HS_ULPI_D0") -> HS_ULPI_D0 | N13: =IFERROR(__xludf.DUMMYFUNCTION("TRIM(REGEXREPLACE(R13 , ""US?ART(._(TX|RX))|."" , ""$1 "") )"),"2_RX") -> 2_RX | O13: =IFERROR(__xludf.DUMMYFUNCTION("TRIM(REGEXREPLACE(Q13 , ""DAC(\d+_OUT\d+)|."" , ""$1 "") )"),"") | P13: =IFERROR(__xludf.DUMMYFUNCTION("TRIM(REGEXREPLACE(REGEXREPLACE(R13, "","", "" ""), ""(EVENTOUT|TRACECLK|TRACED.|SPI._[^ ]*|SAI._[^ ]*|ETH_[^ ]*|QUADSPI_[^ ]*|FMC_[^ ]*|UART._[^ ]*|FDCAN._[^ ]*|DFSDM._[^ ]*|OTG_[^ ]*|TIM\d+_[^ ]*)( |$)"", "" ""))"),"LP USART2_RX LCD_B2 LCD_B5") -> LP USART2_RX LCD_B2 LCD_B5 | Q13: ADC12_INP15 | R13: TIM2_CH4, TIM5_CH4,LPTIM5_OUT,TIM15_CH2,USART2_RX, LCD_B2,OTG_HS_ULPI_D0,ETH_MII_COL, LCD_B5,EVENTOUT
A14: 28 | B14: PA4 | D14: =IF(COUNTIF(ConnectorPins!$F$2:$F$999, B14) > 0, MATCH(B14, ConnectorPins!$F$2:$F$999, 0), IF(COUNTIF(ConnectorPins!$I$2:$I$999, B14) > 0, MATCH(B14, ConnectorPins!$I$2:$I$999, 0) + 35, "")) -> 64 | E14: ADC12_INP18 | F14: DAC1_OUT1 | G14: =IFERROR(__xludf.DUMMYFUNCTION("TRIM(REGEXREPLACE(Q14 , ""ADC(\d+_(INN\d+|INP\d+)*)|."" , ""$1 "") )"),"12_INP18") -> 12_INP18 | I14: =IFERROR(__xludf.DUMMYFUNCTION("TRIM(REGEXREPLACE(R14 , ""SPI(._(MOSI|MISO|SCK))|."" , ""$1 "") )"),"") | J14: =IFERROR(__xludf.DUMMYFUNCTION("TRIM(REGEXREPLACE(R14 , ""FDCAN(._[\w_]+)|."" , ""$1 "") )"),"") | K14: =IFERROR(__xludf.DUMMYFUNCTION("TRIM(REGEXREPLACE(R14 , ""ETH_([\w_]+)|."" , ""$1 "") )"),"") | L14: =IFERROR(__xludf.DUMMYFUNCTION("TRIM(REGEXREPLACE(R14 , ""TIM(._\w+)|."" , ""$1 "") )"),"5_ETR") -> 5_ETR | M14: =IFERROR(__xludf.DUMMYFUNCTION("TRIM(REGEXREPLACE(R14 , ""OTG_([\w_]+)|."" , ""$1 "") )"),"HS_SOF") -> HS_SOF | N14: =IFERROR(__xludf.DUMMYFUNCTION("TRIM(REGEXREPLACE(R14 , ""US?ART(._(TX|RX))|."" , ""$1 "") )"),"") | O14: =IFERROR(__xludf.DUMMYFUNCTION("TRIM(REGEXREPLACE(Q14 , ""DAC(\d+_OUT\d+)|."" , ""$1 "") )"),"1_OUT1") -> 1_OUT1 | P14: =IFERROR(__xludf.DUMMYFUNCTION("TRIM(REGEXREPLACE(REGEXREPLACE(R14, "","", "" ""), ""(EVENTOUT|TRACECLK|TRACED.|SPI._[^ ]*|SAI._[^ ]*|ETH_[^ ]*|QUADSPI_[^ ]*|FMC_[^ ]*|UART._[^ ]*|FDCAN._[^ ]*|DFSDM._[^ ]*|OTG_[^ ]*|TIM\d+_[^ ]*)( |$)"", "" ""))"),"D1PWREN USART2_CK DCMI_HSYNC LCD_VSYNC") -> D1PWREN USART2_CK DCMI_HSYNC LCD_VSYNC | Q14: ADC12_INP18,DAC1_OUT1 | R14: D1PWREN, TIM5_ETR,SPI1_NSS/I2S1_WS,SPI3_NSS/I2S3_WS,USART2_CK, SPI6_NSS,OTG_HS_SOF,DCMI_HSYNC,LCD_VSYNC,EVENTOUT
A15: 29 | B15: PA5 | C15: SPI1_SCK | D15: =IF(COUNTIF(ConnectorPins!$F$2:$F$999, B15) > 0, MATCH(B15, ConnectorPins!$F$2:$F$999, 0), IF(COUNTIF(ConnectorPins!$I$2:$I$999, B15) > 0, MATCH(B15, ConnectorPins!$I$2:$I$999, 0) + 35, "")) | G15: =IFERROR(__xludf.DUMMYFUNCTION("TRIM(REGEXREPLACE(Q15 , ""ADC(\d+_(INN\d+|INP\d+)*)|."" , ""$1 "") )"),"12_INN18 12_INP19") -> 12_INN18 12_INP19 | I15: =IFERROR(__xludf.DUMMYFUNCTION("TRIM(REGEXREPLACE(R15 , ""SPI(._(MOSI|MISO|SCK))|."" , ""$1 "") )"),"1_SCK 6_SCK") -> 1_SCK 6_SCK | J15: =IFERROR(__xludf.DUMMYFUNCTION("TRIM(REGEXREPLACE(R15 , ""FDCAN(._[\w_]+)|."" , ""$1 "") )"),"") | K15: =IFERROR(__xludf.DUMMYFUNCTION("TRIM(REGEXREPLACE(R15 , ""ETH_([\w_]+)|."" , ""$1 "") )"),"") | L15: =IFERROR(__xludf.DUMMYFUNCTION("TRIM(REGEXREPLACE(R15 , ""TIM(._\w+)|."" , ""$1 "") )"),"2_CH1 2_ETR 8_CH1N") -> 2_CH1 2_ETR 8_CH1N | M15: =IFERROR(__xludf.DUMMYFUNCTION("TRIM(REGEXREPLACE(R15 , ""OTG_([\w_]+)|."" , ""$1 "") )"),"HS_ULPI_CK") -> HS_ULPI_CK | N15: =IFERROR(__xludf.DUMMYFUNCTION("TRIM(REGEXREPLACE(R15 , ""US?ART(._(TX|RX))|."" , ""$1 "") )"),"") | O15: =IFERROR(__xludf.DUMMYFUNCTION("TRIM(REGEXREPLACE(Q15 , ""DAC(\d+_OUT\d+)|."" , ""$1 "") )"),"1_OUT2") -> 1_OUT2 | P15: =IFERROR(__xludf.DUMMYFUNCTION("TRIM(REGEXREPLACE(REGEXREPLACE(R15, "","", "" ""), ""(EVENTOUT|TRACECLK|TRACED.|SPI._[^ ]*|SAI._[^ ]*|ETH_[^ ]*|QUADSPI_[^ ]*|FMC_[^ ]*|UART._[^ ]*|FDCAN._[^ ]*|DFSDM._[^ ]*|OTG_[^ ]*|TIM\d+_[^ ]*)( |$)"", "" ""))"),"D2PWREN LCD_R4") -> D2PWREN LCD_R4 | Q15: ADC12_INN18,ADC12_INP19,DAC1_OUT2 | R15: D2PWREN,TIM2_CH1/TIM2_ETR,TIM8_CH1N,SPI1_SCK/I2S1_CK,SPI6_SCK,OTG_HS_ULPI_CK,LCD_R4, EVENTOUT
A16: 30 | B16: PA6 | D16: =IF(COUNTIF(ConnectorPins!$F$2:$F$999, B16) > 0, MATCH(B16, ConnectorPins!$F$2:$F$999, 0), IF(COUNTIF(ConnectorPins!$I$2:$I$999, B16) > 0, MATCH(B16, ConnectorPins!$I$2:$I$999, 0) + 35, "")) -> 65 | G16: =IFERROR(__xludf.DUMMYFUNCTION("TRIM(REGEXREPLACE(Q16 , ""ADC(\d+_(INN\d+|INP\d+)*)|."" , ""$1 "") )"),"12_INP3") -> 12_INP3 | I16: =IFERROR(__xludf.DUMMYFUNCTION("TRIM(REGEXREPLACE(R16 , ""SPI(._(MOSI|MISO|SCK))|."" , ""$1 "") )"),"1_MISO 6_MISO") -> 1_MISO 6_MISO | J16: =IFERROR(__xludf.DUMMYFUNCTION("TRIM(REGEXREPLACE(R16 , ""FDCAN(._[\w_]+)|."" , ""$1 "") )"),"") | K16: =IFERROR(__xludf.DUMMYFUNCTION("TRIM(REGEXREPLACE(R16 , ""ETH_([\w_]+)|."" , ""$1 "") )"),"") | L16: =IFERROR(__xludf.DUMMYFUNCTION("TRIM(REGEXREPLACE(R16 , ""TIM(._\w+)|."" , ""$1 "") )"),"1_BKIN 3_CH1 8_BKIN 8_BKIN_COMP12 1_BKIN_COMP12") -> 1_BKIN 3_CH1 8_BKIN 8_BKIN_COMP12 1_BKIN_COMP12 | M16: =IFERROR(__xludf.DUMMYFUNCTION("TRIM(REGEXREPLACE(R16 , ""OTG_([\w_]+)|."" , ""$1 "") )"),"") | N16: =IFERROR(__xludf.DUMMYFUNCTION("TRIM(REGEXREPLACE(R16 , ""US?ART(._(TX|RX))|."" , ""$1 "") )"),"") | O16: =IFERROR(__xludf.DUMMYFUNCTION("TRIM(REGEXREPLACE(Q16 , ""DAC(\d+_OUT\d+)|."" , ""$1 "") )"),"") | P16: =IFERROR(__xludf.DUMMYFUNCTION("TRIM(REGEXREPLACE(REGEXREPLACE(R16, "","", "" ""), ""(EVENTOUT|TRACECLK|TRACED.|SPI._[^ ]*|SAI._[^ ]*|ETH_[^ ]*|QUADSPI_[^ ]*|FMC_[^ ]*|UART._[^ ]*|FDCAN._[^ ]*|DFSDM._[^ ]*|OTG_[^ ]*|TIM\d+_[^ ]*)( |$)"", "" ""))"),"MDIOS_MDC DCMI_PIXCLK LCD_G2") -> MDIOS_MDC DCMI_PIXCLK LCD_G2 | Q16: ADC12_INP3 | R16: TIM1_BKIN, TIM3_CH1,TIM8_BKIN,SPI1_MISO/I2S1_SDI,SPI6_MISO, TIM13_CH1,TIM8_BKIN_COMP12,MDIOS_MDC,TIM1_BKIN_COMP12,DCMI_PIXCLK, LCD_G2,EVENTOUT
A17: 31 | B17: PA7 | D17: =IF(COUNTIF(ConnectorPins!$F$2:$F$999, B17) > 0, MATCH(B17, ConnectorPins!$F$2:$F$999, 0), IF(COUNTIF(ConnectorPins!$I$2:$I$999, B17) > 0, MATCH(B17, ConnectorPins!$I$2:$I$999, 0) + 35, "")) -> 66 | E17: ETH_RMII_CRS_DV | G17: =IFERROR(__xludf.DUMMYFUNCTION("TRIM(REGEXREPLACE(Q17 , ""ADC(\d+_(INN\d+|INP\d+)*)|."" , ""$1 "") )"),"12_INN3 12_INP7") -> 12_INN3 12_INP7 | I17: =IFERROR(__xludf.DUMMYFUNCTION("TRIM(REGEXREPLACE(R17 , ""SPI(._(MOSI|MISO|SCK))|."" , ""$1 "") )"),"1_MOSI 6_MOSI") -> 1_MOSI 6_MOSI | J17: =IFERROR(__xludf.DUMMYFUNCTION("TRIM(REGEXREPLACE(R17 , ""FDCAN(._[\w_]+)|."" , ""$1 "") )"),"") | K17: =IFERROR(__xludf.DUMMYFUNCTION("TRIM(REGEXREPLACE(R17 , ""ETH_([\w_]+)|."" , ""$1 "") )"),"MII_RX_DV RMII_CRS_DV") -> MII_RX_DV RMII_CRS_DV | L17: =IFERROR(__xludf.DUMMYFUNCTION("TRIM(REGEXREPLACE(R17 , ""TIM(._\w+)|."" , ""$1 "") )"),"1_CH1N 3_CH2 8_CH1N") -> 1_CH1N 3_CH2 8_CH1N | M17: =IFERROR(__xludf.DUMMYFUNCTION("TRIM(REGEXREPLACE(R17 , ""OTG_([\w_]+)|."" , ""$1 "") )"),"") | N17: =IFERROR(__xludf.DUMMYFUNCTION("TRIM(REGEXREPLACE(R17 , ""US?ART(._(TX|RX))|."" , ""$1 "") )"),"") | O17: =IFERROR(__xludf.DUMMYFUNCTION("TRIM(REGEXREPLACE(Q17 , ""DAC(\d+_OUT\d+)|."" , ""$1 "") )"),"") | P17: =IFERROR(__xludf.DUMMYFUNCTION("TRIM(REGEXREPLACE(REGEXREPLACE(R17, "","", "" ""), ""(EVENTOUT|TRACECLK|TRACED.|SPI._[^ ]*|SAI._[^ ]*|ETH_[^ ]*|QUADSPI_[^ ]*|FMC_[^ ]*|UART._[^ ]*|FDCAN._[^ ]*|DFSDM._[^ ]*|OTG_[^ ]*|TIM\d+_[^ ]*)( |$)"", "" ""))"),"") | Q17: ADC12_INN3,ADC12_INP7,OPAMP1_VINM | R17: TIM1_CH1N, TIM3_CH2,TIM8_CH1N,SPI1_MOSI/I2S1_SDO,SPI6_MOSI, TIM14_CH1,ETH_MII_RX_DV/ETH_RMII_CRS_DV,FMC_SDNWE,EVENTOUT
A18: 67 | B18: PA8 | C18: Output/Timer | D18: =IF(COUNTIF(ConnectorPins!$F$2:$F$999, B18) > 0, MATCH(B18, ConnectorPins!$F$2:$F$999, 0), IF(COUNTIF(ConnectorPins!$I$2:$I$999, B18) > 0, MATCH(B18, ConnectorPins!$I$2:$I$999, 0), "")) | G18: =IFERROR(__xludf.DUMMYFUNCTION("TRIM(REGEXREPLACE(Q18 , ""ADC(\d+_(INN\d+|INP\d+)*)|."" , ""$1 "") )"),"") | H18: LED | I18: =IFERROR(__xludf.DUMMYFUNCTION("TRIM(REGEXREPLACE(R18 , ""SPI(._(MOSI|MISO|SCK))|."" , ""$1 "") )"),"") | J18: =IFERROR(__xludf.DUMMYFUNCTION("TRIM(REGEXREPLACE(R18 , ""FDCAN(._[\w_]+)|."" , ""$1 "") )"),"") | K18: =IFERROR(__xludf.DUMMYFUNCTION("TRIM(REGEXREPLACE(R18 , ""ETH_([\w_]+)|."" , ""$1 "") )"),"") | L18: =IFERROR(__xludf.DUMMYFUNCTION("TRIM(REGEXREPLACE(R18 , ""TIM(._\w+)|."" , ""$1 "") )"),"1_CH1 8_BKIN2 8_BKIN2_COMP12") -> 1_CH1 8_BKIN2 8_BKIN2_COMP12 | M18: =IFERROR(__xludf.DUMMYFUNCTION("TRIM(REGEXREPLACE(R18 , ""OTG_([\w_]+)|."" , ""$1 "") )"),"FS_SOF") -> FS_SOF | N18: =IFERROR(__xludf.DUMMYFUNCTION("TRIM(REGEXREPLACE(R18 , ""US?ART(._(TX|RX))|."" , ""$1 "") )"),"7_RX") -> 7_RX | O18: =IFERROR(__xludf.DUMMYFUNCTION("TRIM(REGEXREPLACE(Q18 , ""DAC(\d+_OUT\d+)|."" , ""$1 "") )"),"") | P18: =IFERROR(__xludf.DUMMYFUNCTION("TRIM(REGEXREPLACE(REGEXREPLACE(R18, "","", "" ""), ""(EVENTOUT|TRACECLK|TRACED.|SPI._[^ ]*|SAI._[^ ]*|ETH_[^ ]*|QUADSPI_[^ ]*|FMC_[^ ]*|UART._[^ ]*|FDCAN._[^ ]*|DFSDM._[^ ]*|OTG_[^ ]*|TIM\d+_[^ ]*)( |$)"", "" ""))"),"MCO1 HRTIM_CHB2 I2C3_SCL USART1_CK LCD_B3 LCD_R6") -> MCO1 HRTIM_CHB2 I2C3_SCL USART1_CK LCD_B3 LCD_R6 | R18: MCO1, TIM1_CH1,HRTIM_CHB2,TIM8_BKIN2, I2C3_SCL,USART1_CK,OTG_FS_SOF,UART7_RX,TIM8_BKIN2_COMP12,LCD_B3, LCD_R6,EVENTOUT
A19: 68 | B19: PA9 | C19: USB VBUS detection | I19: =IFERROR(__xludf.DUMMYFUNCTION("TRIM(REGEXREPLACE(R19 , ""SPI(._(MOSI|MISO|SCK))|."" , ""$1 "") )"),"2_SCK") -> 2_SCK | J19: =IFERROR(__xludf.DUMMYFUNCTION("TRIM(REGEXREPLACE(R19 , ""FDCAN(._[\w_]+)|."" , ""$1 "") )"),"") | K19: =IFERROR(__xludf.DUMMYFUNCTION("TRIM(REGEXREPLACE(R19 , ""ETH_([\w_]+)|."" , ""$1 "") )"),"") | L19: =IFERROR(__xludf.DUMMYFUNCTION("TRIM(REGEXREPLACE(R19 , ""TIM(._\w+)|."" , ""$1 "") )"),"1_CH2") -> 1_CH2 | M19: =IFERROR(__xludf.DUMMYFUNCTION("TRIM(REGEXREPLACE(R19 , ""OTG_([\w_]+)|."" , ""$1 "") )"),"") | N19: =IFERROR(__xludf.DUMMYFUNCTION("TRIM(REGEXREPLACE(R19 , ""US?ART(._(TX|RX))|."" , ""$1 "") )"),"1_TX 1_TX") -> 1_TX 1_TX | O19: =IFERROR(__xludf.DUMMYFUNCTION("TRIM(REGEXREPLACE(Q19 , ""DAC(\d+_OUT\d+)|."" , ""$1 "") )"),"") | P19: =IFERROR(__xludf.DUMMYFUNCTION("TRIM(REGEXREPLACE(REGEXREPLACE(R19, "","", "" ""), ""(EVENTOUT|TRACECLK|TRACED.|SPI._[^ ]*|SAI._[^ ]*|ETH_[^ ]*|QUADSPI_[^ ]*|FMC_[^ ]*|UART._[^ ]*|FDCAN._[^ ]*|DFSDM._[^ ]*|OTG_[^ ]*|TIM\d+_[^ ]*)( |$)"", "" ""))"),"HRTIM_CHC1 LP I2C3_SMBA USART1_TX DCMI_D0 LCD_R5") -> HRTIM_CHC1 LP I2C3_SMBA USART1_TX DCMI_D0 LCD_R5 | Q19: OTG_FS_VBUS | R19: TIM1_CH2,HRTIM_CHC1,LPUART1_TX,I2C3_SMBA,SPI2_SCK/I2S2_CK,USART1_TX, DCMI_D0,LCD_R5, EVENTOUT
A20: 34 | B20: PB0 | D20: =IF(COUNTIF(ConnectorPins!$F$2:$F$999, B20) > 0, MATCH(B20, ConnectorPins!$F$2:$F$999, 0), IF(COUNTIF(ConnectorPins!$I$2:$I$999, B20) > 0, MATCH(B20, ConnectorPins!$I$2:$I$999, 0) + 35, "")) -> 46 | G20: =IFERROR(__xludf.DUMMYFUNCTION("TRIM(REGEXREPLACE(Q20 , ""ADC(\d+_(INN\d+|INP\d+)*)|."" , ""$1 "") )"),"12_INN5 12_INP9") -> 12_INN5 12_INP9 | I20: =IFERROR(__xludf.DUMMYFUNCTION("TRIM(REGEXREPLACE(R20 , ""SPI(._(MOSI|MISO|SCK))|."" , ""$1 "") )"),"") | J20: =IFERROR(__xludf.DUMMYFUNCTION("TRIM(REGEXREPLACE(R20 , ""FDCAN(._[\w_]+)|."" , ""$1 "") )"),"") | K20: =IFERROR(__xludf.DUMMYFUNCTION("TRIM(REGEXREPLACE(R20 , ""ETH_([\w_]+)|."" , ""$1 "") )"),"MII_RXD2") -> MII_RXD2 | L20: =IFERROR(__xludf.DUMMYFUNCTION("TRIM(REGEXREPLACE(R20 , ""TIM(._\w+)|."" , ""$1 "") )"),"1_CH2N 3_CH3 8_CH2N") -> 1_CH2N 3_CH3 8_CH2N | M20: =IFERROR(__xludf.DUMMYFUNCTION("TRIM(REGEXREPLACE(R20 , ""OTG_([\w_]+)|."" , ""$1 "") )"),"HS_ULPI_D1") -> HS_ULPI_D1 | N20: =IFERROR(__xludf.DUMMYFUNCTION("TRIM(REGEXREPLACE(R20 , ""US?ART(._(TX|RX))|."" , ""$1 "") )"),"") | O20: =IFERROR(__xludf.DUMMYFUNCTION("TRIM(REGEXREPLACE(Q20 , ""DAC(\d+_OUT\d+)|."" , ""$1 "") )"),"") | P20: =IFERROR(__xludf.DUMMYFUNCTION("TRIM(REGEXREPLACE(REGEXREPLACE(R20, "","", "" ""), ""(EVENTOUT|TRACECLK|TRACED.|SPI._[^ ]*|SAI._[^ ]*|ETH_[^ ]*|QUADSPI_[^ ]*|FMC_[^ ]*|UART._[^ ]*|FDCAN._[^ ]*|DFSDM._[^ ]*|OTG_[^ ]*|TIM\d+_[^ ]*)( |$)"", "" ""))"),"LCD_R3 LCD_G1") -> LCD_R3 LCD_G1 | Q20: ADC12_INN5,ADC12_INP9,OPAMP1_VINP,COMP1_INP | R20: TIM1_CH2N, TIM3_CH3,TIM8_CH2N,DFSDM1_CKOUT,UART4_CTS, LCD_R3,OTG_HS_ULPI_D1,ETH_MII_RXD2,LCD_G1, EVENTOUT
A21: 35 | B21: PB1 | D21: =IF(COUNTIF(ConnectorPins!$F$2:$F$999, B21) > 0, MATCH(B21, ConnectorPins!$F$2:$F$999, 0), IF(COUNTIF(ConnectorPins!$I$2:$I$999, B21) > 0, MATCH(B21, ConnectorPins!$I$2:$I$999, 0) + 35, "")) -> 47 | G21: =IFERROR(__xludf.DUMMYFUNCTION("TRIM(REGEXREPLACE(Q21 , ""ADC(\d+_(INN\d+|INP\d+)*)|."" , ""$1 "") )"),"12_INP5") -> 12_INP5 | I21: =IFERROR(__xludf.DUMMYFUNCTION("TRIM(REGEXREPLACE(R21 , ""SPI(._(MOSI|MISO|SCK))|."" , ""$1 "") )"),"") | J21: =IFERROR(__xludf.DUMMYFUNCTION("TRIM(REGEXREPLACE(R21 , ""FDCAN(._[\w_]+)|."" , ""$1 "") )"),"") | K21: =IFERROR(__xludf.DUMMYFUNCTION("TRIM(REGEXREPLACE(R21 , ""ETH_([\w_]+)|."" , ""$1 "") )"),"MII_RXD3") -> MII_RXD3 | L21: =IFERROR(__xludf.DUMMYFUNCTION("TRIM(REGEXREPLACE(R21 , ""TIM(._\w+)|."" , ""$1 "") )"),"1_CH3N 3_CH4 8_CH3N") -> 1_CH3N 3_CH4 8_CH3N | M21: =IFERROR(__xludf.DUMMYFUNCTION("TRIM(REGEXREPLACE(R21 , ""OTG_([\w_]+)|."" , ""$1 "") )"),"HS_ULPI_D2") -> HS_ULPI_D2 | N21: =IFERROR(__xludf.DUMMYFUNCTION("TRIM(REGEXREPLACE(R21 , ""US?ART(._(TX|RX))|."" , ""$1 "") )"),"") | O21: =IFERROR(__xludf.DUMMYFUNCTION("TRIM(REGEXREPLACE(Q21 , ""DAC(\d+_OUT\d+)|."" , ""$1 "") )"),"") | P21: =IFERROR(__xludf.DUMMYFUNCTION("TRIM(REGEXREPLACE(REGEXREPLACE(R21, "","", "" ""), ""(EVENTOUT|TRACECLK|TRACED.|SPI._[^ ]*|SAI._[^ ]*|ETH_[^ ]*|QUADSPI_[^ ]*|FMC_[^ ]*|UART._[^ ]*|FDCAN._[^ ]*|DFSDM._[^ ]*|OTG_[^ ]*|TIM\d+_[^ ]*)( |$)"", "" ""))"),"LCD_R6 LCD_G0") -> LCD_R6 LCD_G0 | Q21: ADC12_INP5,COMP1_INM | R21: TIM1_CH3N, TIM3_CH4,TIM8_CH3N,DFSDM1_DATIN1,LCD_R6,OTG_HS_ULPI_D2,ETH_MII_RXD3,LCD_G0, EVENTOUT
A22: 46 | B22: PB10 | D22: =IF(COUNTIF(ConnectorPins!$F$2:$F$999, B22) > 0, MATCH(B22, ConnectorPins!$F$2:$F$999, 0), IF(COUNTIF(ConnectorPins!$I$2:$I$999, B22) > 0, MATCH(B22, ConnectorPins!$I$2:$I$999, 0) + 35, "")) -> 54 | F22: TIM2_CH3 | G22: =IFERROR(__xludf.DUMMYFUNCTION("TRIM(REGEXREPLACE(Q22 , ""ADC(\d+_(INN\d+|INP\d+)*)|."" , ""$1 "") )"),"") | I22: =IFERROR(__xludf.DUMMYFUNCTION("TRIM(REGEXREPLACE(R22 , ""SPI(._(MOSI|MISO|SCK))|."" , ""$1 "") )"),"2_SCK") -> 2_SCK | J22: =IFERROR(__xludf.DUMMYFUNCTION("TRIM(REGEXREPLACE(R22 , ""FDCAN(._[\w_]+)|."" , ""$1 "") )"),"") | K22: =IFERROR(__xludf.DUMMYFUNCTION("TRIM(REGEXREPLACE(R22 , ""ETH_([\w_]+)|."" , ""$1 "") )"),"MII_RX_ER") -> MII_RX_ER | L22: =IFERROR(__xludf.DUMMYFUNCTION("TRIM(REGEXREPLACE(R22 , ""TIM(._\w+)|."" , ""$1 "") )"),"2_CH3 2_IN1") -> 2_CH3 2_IN1 | M22: =IFERROR(__xludf.DUMMYFUNCTION("TRIM(REGEXREPLACE(R22 , ""OTG_([\w_]+)|."" , ""$1 "") )"),"HS_ULPI_D3") -> HS_ULPI_D3 | N22: =IFERROR(__xludf.DUMMYFUNCTION("TRIM(REGEXREPLACE(R22 , ""US?ART(._(TX|RX))|."" , ""$1 "") )"),"3_TX") -> 3_TX | O22: =IFERROR(__xludf.DUMMYFUNCTION("TRIM(REGEXREPLACE(Q22 , ""DAC(\d+_OUT\d+)|."" , ""$1 "") )"),"") | P22: =IFERROR(__xludf.DUMMYFUNCTION("TRIM(REGEXREPLACE(REGEXREPLACE(R22, "","", "" ""), ""(EVENTOUT|TRACECLK|TRACED.|SPI._[^ ]*|SAI._[^ ]*|ETH_[^ ]*|QUADSPI_[^ ]*|FMC_[^ ]*|UART._[^ ]*|FDCAN._[^ ]*|DFSDM._[^ ]*|OTG_[^ ]*|TIM\d+_[^ ]*)( |$)"", "" ""))"),"HRTIM_SCOUT LP I2C2_SCL USART3_TX LCD_G4") -> HRTIM_SCOUT LP I2C2_SCL USART3_TX LCD_G4 | R22: TIM2_CH3,HRTIM_SCOUT,LPTIM2_IN1, I2C2_SCL,SPI2_SCK/I2S2_CK,DFSDM1_DATIN7,USART3_TX,QUADSPI_BK1_NCS,OTG_HS_ULPI_D3,ETH_MII_RX_ER,LCD_G4, EVENTOUT
A23: 47 | B23: PB11 | D23: =IF(COUNTIF(ConnectorPins!$F$2:$F$999, B23) > 0, MATCH(B23, ConnectorPins!$F$2:$F$999, 0), IF(COUNTIF(ConnectorPins!$I$2:$I$999, B23) > 0, MATCH(B23, ConnectorPins!$I$2:$I$999, 0) + 35, "")) -> 55 | E23: ETH_RMII_TX_EN | F23: TIM2_CH4 | G23: =IFERROR(__xludf.DUMMYFUNCTION("TRIM(REGEXREPLACE(Q23 , ""ADC(\d+_(INN\d+|INP\d+)*)|."" , ""$1 "") )"),"") | I23: =IFERROR(__xludf.DUMMYFUNCTION("TRIM(REGEXREPLACE(R23 , ""SPI(._(MOSI|MISO|SCK))|."" , ""$1 "") )"),"") | J23: =IFERROR(__xludf.DUMMYFUNCTION("TRIM(REGEXREPLACE(R23 , ""FDCAN(._[\w_]+)|."" , ""$1 "") )"),"") | K23: =IFERROR(__xludf.DUMMYFUNCTION("TRIM(REGEXREPLACE(R23 , ""ETH_([\w_]+)|."" , ""$1 "") )"),"MII_TX_EN RMII_TX_EN") -> MII_TX_EN RMII_TX_EN | L23: =IFERROR(__xludf.DUMMYFUNCTION("TRIM(REGEXREPLACE(R23 , ""TIM(._\w+)|."" , ""$1 "") )"),"2_CH4 2_ETR") -> 2_CH4 2_ETR | M23: =IFERROR(__xludf.DUMMYFUNCTION("TRIM(REGEXREPLACE(R23 , ""OTG_([\w_]+)|."" , ""$1 "") )"),"HS_ULPI_D4") -> HS_ULPI_D4 | N23: =IFERROR(__xludf.DUMMYFUNCTION("TRIM(REGEXREPLACE(R23 , ""US?ART(._(TX|RX))|."" , ""$1 "") )"),"3_RX") -> 3_RX | O23: =IFERROR(__xludf.DUMMYFUNCTION("TRIM(REGEXREPLACE(Q23 , ""DAC(\d+_OUT\d+)|."" , ""$1 "") )"),"") | P23: =IFERROR(__xludf.DUMMYFUNCTION("TRIM(REGEXREPLACE(REGEXREPLACE(R23, "","", "" ""), ""(EVENTOUT|TRACECLK|TRACED.|SPI._[^ ]*|SAI._[^ ]*|ETH_[^ ]*|QUADSPI_[^ ]*|FMC_[^ ]*|UART._[^ ]*|FDCAN._[^ ]*|DFSDM._[^ ]*|OTG_[^ ]*|TIM\d+_[^ ]*)( |$)"", "" ""))"),"HRTIM_SCIN LP I2C2_SDA USART3_RX LCD_G5") -> HRTIM_SCIN LP I2C2_SDA USART3_RX LCD_G5 | R23: TIM2_CH4,HRTIM_SCIN,LPTIM2_ETR,I2C2_SDA,DFSDM1_CKIN7,USART3_RX,OTG_HS_ULPI_D4,ETH_MII_TX_EN/ETH_RMII_TX_EN, LCD_G5,EVENTOUT
A24: 51 | B24: PB12 | D24: =IF(COUNTIF(ConnectorPins!$F$2:$F$999, B24) > 0, MATCH(B24, ConnectorPins!$F$2:$F$999, 0), IF(COUNTIF(ConnectorPins!$I$2:$I$999, B24) > 0, MATCH(B24, ConnectorPins!$I$2:$I$999, 0) + 35, "")) -> 56 | E24: ETH_RMII_TXD0 | F24: FDCAN2_RX | G24: =IFERROR(__xludf.DUMMYFUNCTION("TRIM(REGEXREPLACE(Q24 , ""ADC(\d+_(INN\d+|INP\d+)*)|."" , ""$1 "") )"),"") | I24: =IFERROR(__xludf.DUMMYFUNCTION("TRIM(REGEXREPLACE(R24 , ""SPI(._(MOSI|MISO|SCK))|."" , ""$1 "") )"),"") | J24: =IFERROR(__xludf.DUMMYFUNCTION("TRIM(REGEXREPLACE(R24 , ""FDCAN(._[\w_]+)|."" , ""$1 "") )"),"2_RX") -> 2_RX | K24: =IFERROR(__xludf.DUMMYFUNCTION("TRIM(REGEXREPLACE(R24 , ""ETH_([\w_]+)|."" , ""$1 "") )"),"MII_TXD0 RMII_TXD0") -> MII_TXD0 RMII_TXD0 | L24: =IFERROR(__xludf.DUMMYFUNCTION("TRIM(REGEXREPLACE(R24 , ""TIM(._\w+)|."" , ""$1 "") )"),"1_BKIN 1_BKIN_COMP12") -> 1_BKIN 1_BKIN_COMP12 | M24: =IFERROR(__xludf.DUMMYFUNCTION("TRIM(REGEXREPLACE(R24 , ""OTG_([\w_]+)|."" , ""$1 "") )"),"HS_ULPI_D5 HS_ID") -> HS_ULPI_D5 HS_ID | N24: =IFERROR(__xludf.DUMMYFUNCTION("TRIM(REGEXREPLACE(R24 , ""US?ART(._(TX|RX))|."" , ""$1 "") )"),"5_RX") -> 5_RX | O24: =IFERROR(__xludf.DUMMYFUNCTION("TRIM(REGEXREPLACE(Q24 , ""DAC(\d+_OUT\d+)|."" , ""$1 "") )"),"") | P24: =IFERROR(__xludf.DUMMYFUNCTION("TRIM(REGEXREPLACE(REGEXREPLACE(R24, "","", "" ""), ""(EVENTOUT|TRACECLK|TRACED.|SPI._[^ ]*|SAI._[^ ]*|ETH_[^ ]*|QUADSPI_[^ ]*|FMC_[^ ]*|UART._[^ ]*|FDCAN._[^ ]*|DFSDM._[^ ]*|OTG_[^ ]*|TIM\d+_[^ ]*)( |$)"", "" ""))"),"I2C2_SMBA USART3_CK") -> I2C2_SMBA USART3_CK | R24: TIM1_BKIN, I2C2_SMBA,SPI2_NSS/I2S2_WS,DFSDM1_DATIN1,USART3_CK,FDCAN2_RX,OTG_HS_ULPI_D5,ETH_MII_TXD0/ETH_RMII_TXD0, OTG_HS_ID,TIM1_BKIN_COMP12,UART5_RX, EVENTOUT
A25: 52 | B25: PB13 | D25: =IF(COUNTIF(ConnectorPins!$F$2:$F$999, B25) > 0, MATCH(B25, ConnectorPins!$F$2:$F$999, 0), IF(COUNTIF(ConnectorPins!$I$2:$I$999, B25) > 0, MATCH(B25, ConnectorPins!$I$2:$I$999, 0) + 35, "")) -> 57 | E25: ETH_RMII_TXD1 | F25: FDCAN2_TX | G25: =IFERROR(__xludf.DUMMYFUNCTION("TRIM(REGEXREPLACE(Q25 , ""ADC(\d+_(INN\d+|INP\d+)*)|."" , ""$1 "") )"),"") | I25: =IFERROR(__xludf.DUMMYFUNCTION("TRIM(REGEXREPLACE(R25 , ""SPI(._(MOSI|MISO|SCK))|."" , ""$1 "") )"),"2_SCK") -> 2_SCK | J25: =IFERROR(__xludf.DUMMYFUNCTION("TRIM(REGEXREPLACE(R25 , ""FDCAN(._[\w_]+)|."" , ""$1 "") )"),"2_TX") -> 2_TX | K25: =IFERROR(__xludf.DUMMYFUNCTION("TRIM(REGEXREPLACE(R25 , ""ETH_([\w_]+)|."" , ""$1 "") )"),"MII_TXD1 RMII_TXD1") -> MII_TXD1 RMII_TXD1 | L25: =IFERROR(__xludf.DUMMYFUNCTION("TRIM(REGEXREPLACE(R25 , ""TIM(._\w+)|."" , ""$1 "") )"),"1_CH1N 2_OUT") -> 1_CH1N 2_OUT | M25: =IFERROR(__xludf.DUMMYFUNCTION("TRIM(REGEXREPLACE(R25 , ""OTG_([\w_]+)|."" , ""$1 "") )"),"HS_ULPI_D6") -> HS_ULPI_D6 | N25: =IFERROR(__xludf.DUMMYFUNCTION("TRIM(REGEXREPLACE(R25 , ""US?ART(._(TX|RX))|."" , ""$1 "") )"),"5_TX") -> 5_TX | O25: =IFERROR(__xludf.DUMMYFUNCTION("TRIM(REGEXREPLACE(Q25 , ""DAC(\d+_OUT\d+)|."" , ""$1 "") )"),"") | P25: =IFERROR(__xludf.DUMMYFUNCTION("TRIM(REGEXREPLACE(REGEXREPLACE(R25, "","", "" ""), ""(EVENTOUT|TRACECLK|TRACED.|SPI._[^ ]*|SAI._[^ ]*|ETH_[^ ]*|QUADSPI_[^ ]*|FMC_[^ ]*|UART._[^ ]*|FDCAN._[^ ]*|DFSDM._[^ ]*|OTG_[^ ]*|TIM\d+_[^ ]*)( |$)"", "" ""))"),"LP USART3_CTS/USART3_NSS") -> LP USART3_CTS/USART3_NSS | Q25: OTG_HS_VBUS | R25: TIM1_CH1N,LPTIM2_OUT,SPI2_SCK/I2S2_CK,DFSDM1_CKIN1,USART3_CTS/USART3_NSS, FDCAN2_TX,OTG_HS_ULPI_D6,ETH_MII_TXD1/ETH_RMII_TXD1, UART5_TX,EVENTOUT
A26: 53 | B26: PB14 | C26: SPI2_MISO | D26: =IF(COUNTIF(ConnectorPins!$F$2:$F$999, B26) > 0, MATCH(B26, ConnectorPins!$F$2:$F$999, 0), IF(COUNTIF(ConnectorPins!$I$2:$I$999, B26) > 0, MATCH(B26, ConnectorPins!$I$2:$I$999, 0) + 35, "")) | G26: =IFERROR(__xludf.DUMMYFUNCTION("TRIM(REGEXREPLACE(Q26 , ""ADC(\d+_(INN\d+|INP\d+)*)|."" , ""$1 "") )"),"") | I26: =IFERROR(__xludf.DUMMYFUNCTION("TRIM(REGEXREPLACE(R26 , ""SPI(._(MOSI|MISO|SCK))|."" , ""$1 "") )"),"2_MISO") -> 2_MISO | J26: =IFERROR(__xludf.DUMMYFUNCTION("TRIM(REGEXREPLACE(R26 , ""FDCAN(._[\w_]+)|."" , ""$1 "") )"),"") | K26: =IFERROR(__xludf.DUMMYFUNCTION("TRIM(REGEXREPLACE(R26 , ""ETH_([\w_]+)|."" , ""$1 "") )"),"") | L26: =IFERROR(__xludf.DUMMYFUNCTION("TRIM(REGEXREPLACE(R26 , ""TIM(._\w+)|."" , ""$1 "") )"),"1_CH2N 8_CH2N") -> 1_CH2N 8_CH2N | M26: =IFERROR(__xludf.DUMMYFUNCTION("TRIM(REGEXREPLACE(R26 , ""OTG_([\w_]+)|."" , ""$1 "") )"),"HS_DM") -> HS_DM | N26: =IFERROR(__xludf.DUMMYFUNCTION("TRIM(REGEXREPLACE(R26 , ""US?ART(._(TX|RX))|."" , ""$1 "") )"),"1_TX") -> 1_TX | O26: =IFERROR(__xludf.DUMMYFUNCTION("TRIM(REGEXREPLACE(Q26 , ""DAC(\d+_OUT\d+)|."" , ""$1 "") )"),"") | P26: =IFERROR(__xludf.DUMMYFUNCTION("TRIM(REGEXREPLACE(REGEXREPLACE(R26, "","", "" ""), ""(EVENTOUT|TRACECLK|TRACED.|SPI._[^ ]*|SAI._[^ ]*|ETH_[^ ]*|QUADSPI_[^ ]*|FMC_[^ ]*|UART._[^ ]*|FDCAN._[^ ]*|DFSDM._[^ ]*|OTG_[^ ]*|TIM\d+_[^ ]*)( |$)"", "" ""))"),"USART1_TX USART3_RTS/USART3_DE SDMMC2_D0") -> USART1_TX USART3_RTS/USART3_DE SDMMC2_D0 | R26: TIM1_CH2N,TIM12_CH1,TIM8_CH2N,USART1_TX,SPI2_MISO/I2S2_SDI,DFSDM1_DATIN2,USART3_RTS/USART3_DE,UART4_RTS/UART4_DE, SDMMC2_D0,OTG_HS_DM,EVENTOUT
A27: 54 | B27: PB15 | C27: SPI2_MOSI | D27: =IF(COUNTIF(ConnectorPins!$F$2:$F$999, B27) > 0, MATCH(B27, ConnectorPins!$F$2:$F$999, 0), IF(COUNTIF(ConnectorPins!$I$2:$I$999, B27) > 0, MATCH(B27, ConnectorPins!$I$2:$I$999, 0), "")) | G27: =IFERROR(__xludf.DUMMYFUNCTION("TRIM(REGEXREPLACE(Q27 , ""ADC(\d+_(INN\d+|INP\d+)*)|."" , ""$1 "") )"),"") | I27: =IFERROR(__xludf.DUMMYFUNCTION("TRIM(REGEXREPLACE(R27 , ""SPI(._(MOSI|MISO|SCK))|."" , ""$1 "") )"),"2_MOSI") -> 2_MOSI | J27: =IFERROR(__xludf.DUMMYFUNCTION("TRIM(REGEXREPLACE(R27 , ""FDCAN(._[\w_]+)|."" , ""$1 "") )"),"") | K27: =IFERROR(__xludf.DUMMYFUNCTION("TRIM(REGEXREPLACE(R27 , ""ETH_([\w_]+)|."" , ""$1 "") )"),"") | L27: =IFERROR(__xludf.DUMMYFUNCTION("TRIM(REGEXREPLACE(R27 , ""TIM(._\w+)|."" , ""$1 "") )"),"1_CH3N 8_CH3N") -> 1_CH3N 8_CH3N | M27: =IFERROR(__xludf.DUMMYFUNCTION("TRIM(REGEXREPLACE(R27 , ""OTG_([\w_]+)|."" , ""$1 "") )"),"HS_DP") -> HS_DP | N27: =IFERROR(__xludf.DUMMYFUNCTION("TRIM(REGEXREPLACE(R27 , ""US?ART(._(TX|RX))|."" , ""$1 "") )"),"1_RX") -> 1_RX | O27: =IFERROR(__xludf.DUMMYFUNCTION("TRIM(REGEXREPLACE(Q27 , ""DAC(\d+_OUT\d+)|."" , ""$1 "") )"),"") | P27: =IFERROR(__xludf.DUMMYFUNCTION("TRIM(REGEXREPLACE(REGEXREPLACE(R27, "","", "" ""), ""(EVENTOUT|TRACECLK|TRACED.|SPI._[^ ]*|SAI._[^ ]*|ETH_[^ ]*|QUADSPI_[^ ]*|FMC_[^ ]*|UART._[^ ]*|FDCAN._[^ ]*|DFSDM._[^ ]*|OTG_[^ ]*|TIM\d+_[^ ]*)( |$)"", "" ""))"),"RTC_REFIN USART1_RX SDMMC2_D1") -> RTC_REFIN USART1_RX SDMMC2_D1 | R27: RTC_REFIN,TIM1_CH3N,TIM12_CH2,TIM8_CH3N,USART1_RX,SPI2_MOSI/I2S2_SDO,DFSDM1_CKIN2,UART4_CTS,SDMMC2_D1,OTG_HS_DP,EVENTOUT
A28: 36 | B28: PB2 | D28: =IF(COUNTIF(ConnectorPins!$F$2:$F$999, B28) > 0, MATCH(B28, ConnectorPins!$F$2:$F$999, 0), IF(COUNTIF(ConnectorPins!$I$2:$I$999, B28) > 0, MATCH(B28, ConnectorPins!$I$2:$I$999, 0) + 35, "")) | G28: =IFERROR(__xludf.DUMMYFUNCTION("TRIM(REGEXREPLACE(Q28 , ""ADC(\d+_(INN\d+|INP\d+)*)|."" , ""$1 "") )"),"") | I28: =IFERROR(__xludf.DUMMYFUNCTION("TRIM(REGEXREPLACE(R28 , ""SPI(._(MOSI|MISO|SCK))|."" , ""$1 "") )"),"3_MOSI") -> 3_MOSI | J28: =IFERROR(__xludf.DUMMYFUNCTION("TRIM(REGEXREPLACE(R28 , ""FDCAN(._[\w_]+)|."" , ""$1 "") )"),"") | K28: =IFERROR(__xludf.DUMMYFUNCTION("TRIM(REGEXREPLACE(R28 , ""ETH_([\w_]+)|."" , ""$1 "") )"),"") | L28: =IFERROR(__xludf.DUMMYFUNCTION("TRIM(REGEXREPLACE(R28 , ""TIM(._\w+)|."" , ""$1 "") )"),"") | M28: =IFERROR(__xludf.DUMMYFUNCTION("TRIM(REGEXREPLACE(R28 , ""OTG_([\w_]+)|."" , ""$1 "") )"),"") | N28: =IFERROR(__xludf.DUMMYFUNCTION("TRIM(REGEXREPLACE(R28 , ""US?ART(._(TX|RX))|."" , ""$1 "") )"),"") | O28: =IFERROR(__xludf.DUMMYFUNCTION("TRIM(REGEXREPLACE(Q28 , ""DAC(\d+_OUT\d+)|."" , ""$1 "") )"),"") | P28: =IFERROR(__xludf.DUMMYFUNCTION("TRIM(REGEXREPLACE(REGEXREPLACE(R28, "","", "" ""), ""(EVENTOUT|TRACECLK|TRACED.|SPI._[^ ]*|SAI._[^ ]*|ETH_[^ ]*|QUADSPI_[^ ]*|FMC_[^ ]*|UART._[^ ]*|FDCAN._[^ ]*|DFSDM._[^ ]*|OTG_[^ ]*|TIM\d+_[^ ]*)( |$)"", "" ""))"),"RTC_OUT") -> RTC_OUT | Q28: COMP1_INP | R28: RTC_OUT, SAI1_D1,DFSDM1_CKIN1,SAI1_SD_A,SPI3_MOSI/I2S3_SDO,SAI4_SD_A,QUADSPI_CLK,SAI4_D1, EVENTOUT
A29: 89 | B29: PB3(JTDO/TRACESWO) | C29: SWO | D29: =IF(COUNTIF(ConnectorPins!$F$2:$F$999, B29) > 0, MATCH(B29, ConnectorPins!$F$2:$F$999, 0), IF(COUNTIF(ConnectorPins!$I$2:$I$999, B29) > 0, MATCH(B29, ConnectorPins!$I$2:$I$999, 0), "")) | G29: =IFERROR(__xludf.DUMMYFUNCTION("TRIM(REGEXREPLACE(Q29 , ""ADC(\d+_(INN\d+|INP\d+)*)|."" , ""$1 "") )"),"") | I29: =IFERROR(__xludf.DUMMYFUNCTION("TRIM(REGEXREPLACE(R29 , ""SPI(._(MOSI|MISO|SCK))|."" , ""$1 "") )"),"1_SCK 3_SCK 6_SCK") -> 1_SCK 3_SCK 6_SCK | J29: =IFERROR(__xludf.DUMMYFUNCTION("TRIM(REGEXREPLACE(R29 , ""FDCAN(._[\w_]+)|."" , ""$1 "") )"),"") | K29: =IFERROR(__xludf.DUMMYFUNCTION("TRIM(REGEXREPLACE(R29 , ""ETH_([\w_]+)|."" , ""$1 "") )"),"") | L29: =IFERROR(__xludf.DUMMYFUNCTION("TRIM(REGEXREPLACE(R29 , ""TIM(._\w+)|."" , ""$1 "") )"),"2_CH2") -> 2_CH2 | M29: =IFERROR(__xludf.DUMMYFUNCTION("TRIM(REGEXREPLACE(R29 , ""OTG_([\w_]+)|."" , ""$1 "") )"),"") | N29: =IFERROR(__xludf.DUMMYFUNCTION("TRIM(REGEXREPLACE(R29 , ""US?ART(._(TX|RX))|."" , ""$1 "") )"),"7_RX") -> 7_RX | O29: =IFERROR(__xludf.DUMMYFUNCTION("TRIM(REGEXREPLACE(Q29 , ""DAC(\d+_OUT\d+)|."" , ""$1 "") )"),"") | P29: =IFERROR(__xludf.DUMMYFUNCTION("TRIM(REGEXREPLACE(REGEXREPLACE(R29, "","", "" ""), ""(EVENTOUT|TRACECLK|TRACED.|SPI._[^ ]*|SAI._[^ ]*|ETH_[^ ]*|QUADSPI_[^ ]*|FMC_[^ ]*|UART._[^ ]*|FDCAN._[^ ]*|DFSDM._[^ ]*|OTG_[^ ]*|TIM\d+_[^ ]*)( |$)"", "" ""))"),"JTDO/TRACESWO HRTIM_FLT4 SDMMC2_D2 CRS_SYNC") -> JTDO/TRACESWO HRTIM_FLT4 SDMMC2_D2 CRS_SYNC | R29: JTDO/TRACESWO,TIM2_CH2,HRTIM_FLT4,SPI1_SCK/I2S1_CK,SPI3_SCK/I2S3_CK,SPI6_SCK,SDMMC2_D2,CRS_SYNC, UART7_RX,EVENTOUT
A30: 90 | B30: PB4(NJTRST) | C30: SPI1_MISO | D30: =IF(COUNTIF(ConnectorPins!$F$2:$F$999, B30) > 0, MATCH(B30, ConnectorPins!$F$2:$F$999, 0), IF(COUNTIF(ConnectorPins!$I$2:$I$999, B30) > 0, MATCH(B30, ConnectorPins!$I$2:$I$999, 0), "")) | G30: =IFERROR(__xludf.DUMMYFUNCTION("TRIM(REGEXREPLACE(Q30 , ""ADC(\d+_(INN\d+|INP\d+)*)|."" , ""$1 "") )"),"") | I30: =IFERROR(__xludf.DUMMYFUNCTION("TRIM(REGEXREPLACE(R30 , ""SPI(._(MOSI|MISO|SCK))|."" , ""$1 "") )"),"1_MISO 3_MISO 6_MISO") -> 1_MISO 3_MISO 6_MISO | J30: =IFERROR(__xludf.DUMMYFUNCTION("TRIM(REGEXREPLACE(R30 , ""FDCAN(._[\w_]+)|."" , ""$1 "") )"),"") | K30: =IFERROR(__xludf.DUMMYFUNCTION("TRIM(REGEXREPLACE(R30 , ""ETH_([\w_]+)|."" , ""$1 "") )"),"") | L30: =IFERROR(__xludf.DUMMYFUNCTION("TRIM(REGEXREPLACE(R30 , ""TIM(._\w+)|."" , ""$1 "") )"),"3_CH1") -> 3_CH1 | M30: =IFERROR(__xludf.DUMMYFUNCTION("TRIM(REGEXREPLACE(R30 , ""OTG_([\w_]+)|."" , ""$1 "") )"),"") | N30: =IFERROR(__xludf.DUMMYFUNCTION("TRIM(REGEXREPLACE(R30 , ""US?ART(._(TX|RX))|."" , ""$1 "") )"),"7_TX") -> 7_TX | O30: =IFERROR(__xludf.DUMMYFUNCTION("TRIM(REGEXREPLACE(Q30 , ""DAC(\d+_OUT\d+)|."" , ""$1 "") )"),"") | P30: =IFERROR(__xludf.DUMMYFUNCTION("TRIM(REGEXREPLACE(REGEXREPLACE(R30, "","", "" ""), ""(EVENTOUT|TRACECLK|TRACED.|SPI._[^ ]*|SAI._[^ ]*|ETH_[^ ]*|QUADSPI_[^ ]*|FMC_[^ ]*|UART._[^ ]*|FDCAN._[^ ]*|DFSDM._[^ ]*|OTG_[^ ]*|TIM\d+_[^ ]*)( |$)"", "" ""))"),"NJTRST HRTIM_EEV6 SDMMC2_D3") -> NJTRST HRTIM_EEV6 SDMMC2_D3 | R30: NJTRST, TIM16_BKIN,TIM3_CH1,HRTIM_EEV6,SPI1_MISO/I2S1_SDI,SPI3_MISO/I2S3_SDI,SPI2_NSS/I2S2_WS,SPI6_MISO,SDMMC2_D3,UART7_TX, EVENTOUT
A31: 91 | B31: PB5 | D31: =IF(COUNTIF(ConnectorPins!$F$2:$F$999, B31) > 0, MATCH(B31, ConnectorPins!$F$2:$F$999, 0), IF(COUNTIF(ConnectorPins!$I$2:$I$999, B31) > 0, MATCH(B31, ConnectorPins!$I$2:$I$999, 0), "")) -> 13 | E31: FDCAN2_RX | F31: UART5_RX | G31: =IFERROR(__xludf.DUMMYFUNCTION("TRIM(REGEXREPLACE(Q31 , ""ADC(\d+_(INN\d+|INP\d+)*)|."" , ""$1 "") )"),"") | I31: =IFERROR(__xludf.DUMMYFUNCTION("TRIM(REGEXREPLACE(R31 , ""SPI(._(MOSI|MISO|SCK))|."" , ""$1 "") )"),"1_MOSI 3_MOSI 6_MOSI") -> 1_MOSI 3_MOSI 6_MOSI | J31: =IFERROR(__xludf.DUMMYFUNCTION("TRIM(REGEXREPLACE(R31 , ""FDCAN(._[\w_]+)|."" , ""$1 "") )"),"2_RX") -> 2_RX | K31: =IFERROR(__xludf.DUMMYFUNCTION("TRIM(REGEXREPLACE(R31 , ""ETH_([\w_]+)|."" , ""$1 "") )"),"PPS_OUT") -> PPS_OUT | L31: =IFERROR(__xludf.DUMMYFUNCTION("TRIM(REGEXREPLACE(R31 , ""TIM(._\w+)|."" , ""$1 "") )"),"3_CH2") -> 3_CH2 | M31: =IFERROR(__xludf.DUMMYFUNCTION("TRIM(REGEXREPLACE(R31 , ""OTG_([\w_]+)|."" , ""$1 "") )"),"HS_ULPI_D7") -> HS_ULPI_D7 | N31: =IFERROR(__xludf.DUMMYFUNCTION("TRIM(REGEXREPLACE(R31 , ""US?ART(._(TX|RX))|."" , ""$1 "") )"),"5_RX") -> 5_RX | O31: =IFERROR(__xludf.DUMMYFUNCTION("TRIM(REGEXREPLACE(Q31 , ""DAC(\d+_OUT\d+)|."" , ""$1 "") )"),"") | P31: =IFERROR(__xludf.DUMMYFUNCTION("TRIM(REGEXREPLACE(REGEXREPLACE(R31, "","", "" ""), ""(EVENTOUT|TRACECLK|TRACED.|SPI._[^ ]*|SAI._[^ ]*|ETH_[^ ]*|QUADSPI_[^ ]*|FMC_[^ ]*|UART._[^ ]*|FDCAN._[^ ]*|DFSDM._[^ ]*|OTG_[^ ]*|TIM\d+_[^ ]*)( |$)"", "" ""))"),"HRTIM_EEV7 I2C1_SMBA I2C4_SMBA DCMI_D10") -> HRTIM_EEV7 I2C1_SMBA I2C4_SMBA DCMI_D10 | R31: TIM17_BKIN, TIM3_CH2,HRTIM_EEV7,I2C1_SMBA,SPI1_MOSI/I2S1_SDO,I2C4_SMBA,SPI3_MOSI/I2S3_SDO,SPI6_MOSI,FDCAN2_RX,OTG_HS_ULPI_D7,ETH_PPS_OUT,FMC_SDCKE1,DCMI_D10, UART5_RX,EVENTOUT
A32: 92 | B32: PB6 | D32: =IF(COUNTIF(ConnectorPins!$F$2:$F$999, B32) > 0, MATCH(B32, ConnectorPins!$F$2:$F$999, 0), IF(COUNTIF(ConnectorPins!$I$2:$I$999, B32) > 0, MATCH(B32, ConnectorPins!$I$2:$I$999, 0), "")) -> 14 | E32: FDCAN2_TX | F32: UART5_TX | G32: =IFERROR(__xludf.DUMMYFUNCTION("TRIM(REGEXREPLACE(Q32 , ""ADC(\d+_(INN\d+|INP\d+)*)|."" , ""$1 "") )"),"") | I32: =IFERROR(__xludf.DUMMYFUNCTION("TRIM(REGEXREPLACE(R32 , ""SPI(._(MOSI|MISO|SCK))|."" , ""$1 "") )"),"") | J32: =IFERROR(__xludf.DUMMYFUNCTION("TRIM(REGEXREPLACE(R32 , ""FDCAN(._[\w_]+)|."" , ""$1 "") )"),"2_TX") -> 2_TX | K32: =IFERROR(__xludf.DUMMYFUNCTION("TRIM(REGEXREPLACE(R32 , ""ETH_([\w_]+)|."" , ""$1 "") )"),"") | L32: =IFERROR(__xludf.DUMMYFUNCTION("TRIM(REGEXREPLACE(R32 , ""TIM(._\w+)|."" , ""$1 "") )"),"4_CH1") -> 4_CH1 | M32: =IFERROR(__xludf.DUMMYFUNCTION("TRIM(REGEXREPLACE(R32 , ""OTG_([\w_]+)|."" , ""$1 "") )"),"") | N32: =IFERROR(__xludf.DUMMYFUNCTION("TRIM(REGEXREPLACE(R32 , ""US?ART(._(TX|RX))|."" , ""$1 "") )"),"1_TX 1_TX 5_TX") -> 1_TX 1_TX 5_TX | O32: =IFERROR(__xludf.DUMMYFUNCTION("TRIM(REGEXREPLACE(Q32 , ""DAC(\d+_OUT\d+)|."" , ""$1 "") )"),"") | P32: =IFERROR(__xludf.DUMMYFUNCTION("TRIM(REGEXREPLACE(REGEXREPLACE(R32, "","", "" ""), ""(EVENTOUT|TRACECLK|TRACED.|SPI._[^ ]*|SAI._[^ ]*|ETH_[^ ]*|QUADSPI_[^ ]*|FMC_[^ ]*|UART._[^ ]*|FDCAN._[^ ]*|DFSDM._[^ ]*|OTG_[^ ]*|TIM\d+_[^ ]*)( |$)"", "" ""))"),"HRTIM_EEV8 I2C1_SCL CEC I2C4_SCL USART1_TX LP DCMI_D5") -> HRTIM_EEV8 I2C1_SCL CEC I2C4_SCL USART1_TX LP DCMI_D5 | R32: TIM16_CH1N,TIM4_CH1,HRTIM_EEV8,I2C1_SCL, CEC,I2C4_SCL, USART1_TX,LPUART1_TX,FDCAN2_TX,QUADSPI_BK1_NCS,DFSDM1_DATIN5,FMC_SDNE1, DCMI_D5,UART5_TX, EVENTOUT
A33: 93 | B33: PB7 | D33: =IF(COUNTIF(ConnectorPins!$F$2:$F$999, B33) > 0, MATCH(B33, ConnectorPins!$F$2:$F$999, 0), IF(COUNTIF(ConnectorPins!$I$2:$I$999, B33) > 0, MATCH(B33, ConnectorPins!$I$2:$I$999, 0), "")) -> 15 | G33: =IFERROR(__xludf.DUMMYFUNCTION("TRIM(REGEXREPLACE(Q33 , ""ADC(\d+_(INN\d+|INP\d+)*)|."" , ""$1 "") )"),"") | I33: =IFERROR(__xludf.DUMMYFUNCTION("TRIM(REGEXREPLACE(R33 , ""SPI(._(MOSI|MISO|SCK))|."" , ""$1 "") )"),"") | J33: =IFERROR(__xludf.DUMMYFUNCTION("TRIM(REGEXREPLACE(R33 , ""FDCAN(._[\w_]+)|."" , ""$1 "") )"),"") | K33: =IFERROR(__xludf.DUMMYFUNCTION("TRIM(REGEXREPLACE(R33 , ""ETH_([\w_]+)|."" , ""$1 "") )"),"") | L33: =IFERROR(__xludf.DUMMYFUNCTION("TRIM(REGEXREPLACE(R33 , ""TIM(._\w+)|."" , ""$1 "") )"),"4_CH2") -> 4_CH2 | M33: =IFERROR(__xludf.DUMMYFUNCTION("TRIM(REGEXREPLACE(R33 , ""OTG_([\w_]+)|."" , ""$1 "") )"),"") | N33: =IFERROR(__xludf.DUMMYFUNCTION("TRIM(REGEXREPLACE(R33 , ""US?ART(._(TX|RX))|."" , ""$1 "") )"),"1_RX 1_RX") -> 1_RX 1_RX | O33: =IFERROR(__xludf.DUMMYFUNCTION("TRIM(REGEXREPLACE(Q33 , ""DAC(\d+_OUT\d+)|."" , ""$1 "") )"),"") | P33: =IFERROR(__xludf.DUMMYFUNCTION("TRIM(REGEXREPLACE(REGEXREPLACE(R33, "","", "" ""), ""(EVENTOUT|TRACECLK|TRACED.|SPI._[^ ]*|SAI._[^ ]*|ETH_[^ ]*|QUADSPI_[^ ]*|FMC_[^ ]*|UART._[^ ]*|FDCAN._[^ ]*|DFSDM._[^ ]*|OTG_[^ ]*|TIM\d+_[^ ]*)( |$)"", "" ""))"),"HRTIM_EEV9 I2C1_SDA I2C4_SDA USART1_RX LP DCMI_VSYNC") -> HRTIM_EEV9 I2C1_SDA I2C4_SDA USART1_RX LP DCMI_VSYNC | Q33: PVD_IN | R33: TIM17_CH1N,TIM4_CH2,HRTIM_EEV9,I2C1_SDA, I2C4_SDA,USART1_RX,LPUART1_RX,DFSDM1_CKIN5,FMC_NL, DCMI_VSYNC,EVENTOUT
A34: 95 | B34: PB8 | D34: =IF(COUNTIF(ConnectorPins!$F$2:$F$999, B34) > 0, MATCH(B34, ConnectorPins!$F$2:$F$999, 0), IF(COUNTIF(ConnectorPins!$I$2:$I$999, B34) > 0, MATCH(B34, ConnectorPins!$I$2:$I$999, 0), "")) -> 16 | E34: FDCAN1_RX | G34: =IFERROR(__xludf.DUMMYFUNCTION("TRIM(REGEXREPLACE(Q34 , ""ADC(\d+_(INN\d+|INP\d+)*)|."" , ""$1 "") )"),"") | I34: =IFERROR(__xludf.DUMMYFUNCTION("TRIM(REGEXREPLACE(R34 , ""SPI(._(MOSI|MISO|SCK))|."" , ""$1 "") )"),"") | J34: =IFERROR(__xludf.DUMMYFUNCTION("TRIM(REGEXREPLACE(R34 , ""FDCAN(._[\w_]+)|."" , ""$1 "") )"),"1_RX") -> 1_RX | K34: =IFERROR(__xludf.DUMMYFUNCTION("TRIM(REGEXREPLACE(R34 , ""ETH_([\w_]+)|."" , ""$1 "") )"),"MII_TXD3") -> MII_TXD3 | L34: =IFERROR(__xludf.DUMMYFUNCTION("TRIM(REGEXREPLACE(R34 , ""TIM(._\w+)|."" , ""$1 "") )"),"4_CH3") -> 4_CH3 | M34: =IFERROR(__xludf.DUMMYFUNCTION("TRIM(REGEXREPLACE(R34 , ""OTG_([\w_]+)|."" , ""$1 "") )"),"") | N34: =IFERROR(__xludf.DUMMYFUNCTION("TRIM(REGEXREPLACE(R34 , ""US?ART(._(TX|RX))|."" , ""$1 "") )"),"4_RX") -> 4_RX | O34: =IFERROR(__xludf.DUMMYFUNCTION("TRIM(REGEXREPLACE(Q34 , ""DAC(\d+_OUT\d+)|."" , ""$1 "") )"),"") | P34: =IFERROR(__xludf.DUMMYFUNCTION("TRIM(REGEXREPLACE(REGEXREPLACE(R34, "","", "" ""), ""(EVENTOUT|TRACECLK|TRACED.|SPI._[^ ]*|SAI._[^ ]*|ETH_[^ ]*|QUADSPI_[^ ]*|FMC_[^ ]*|UART._[^ ]*|FDCAN._[^ ]*|DFSDM._[^ ]*|OTG_[^ ]*|TIM\d+_[^ ]*)( |$)"", "" ""))"),"I2C1_SCL I2C4_SCL SDMMC1_CKIN SDMMC2_D4 SDMMC1_D4 DCMI_D6 LCD_B6") -> I2C1_SCL I2C4_SCL SDMMC1_CKIN SDMMC2_D4 SDMMC1_D4 DCMI_D6 LCD_B6 | R34: TIM16_CH1, TIM4_CH3,DFSDM1_CKIN7,I2C1_SCL, I2C4_SCL,SDMMC1_CKIN,UART4_RX,FDCAN1_RX,SDMMC2_D4,ETH_MII_TXD3,SDMMC1_D4, DCMI_D6,LCD_B6, EVENTOUT
A35: 96 | B35: PB9 | D35: =IF(COUNTIF(ConnectorPins!$F$2:$F$999, B35) > 0, MATCH(B35, ConnectorPins!$F$2:$F$999, 0), IF(COUNTIF(ConnectorPins!$I$2:$I$999, B35) > 0, MATCH(B35, ConnectorPins!$I$2:$I$999, 0), "")) -> 17 | E35: FDCAN1_TX | G35: =IFERROR(__xludf.DUMMYFUNCTION("TRIM(REGEXREPLACE(Q35 , ""ADC(\d+_(INN\d+|INP\d+)*)|."" , ""$1 "") )"),"") | I35: =IFERROR(__xludf.DUMMYFUNCTION("TRIM(REGEXREPLACE(R35 , ""SPI(._(MOSI|MISO|SCK))|."" , ""$1 "") )"),"") | J35: =IFERROR(__xludf.DUMMYFUNCTION("TRIM(REGEXREPLACE(R35 , ""FDCAN(._[\w_]+)|."" , ""$1 "") )"),"1_TX") -> 1_TX | K35: =IFERROR(__xludf.DUMMYFUNCTION("TRIM(REGEXREPLACE(R35 , ""ETH_([\w_]+)|."" , ""$1 "") )"),"") | L35: =IFERROR(__xludf.DUMMYFUNCTION("TRIM(REGEXREPLACE(R35 , ""TIM(._\w+)|."" , ""$1 "") )"),"4_CH4") -> 4_CH4 | M35: =IFERROR(__xludf.DUMMYFUNCTION("TRIM(REGEXREPLACE(R35 , ""OTG_([\w_]+)|."" , ""$1 "") )"),"") | N35: =IFERROR(__xludf.DUMMYFUNCTION("TRIM(REGEXREPLACE(R35 , ""US?ART(._(TX|RX))|."" , ""$1 "") )"),"4_TX") -> 4_TX | O35: =IFERROR(__xludf.DUMMYFUNCTION("TRIM(REGEXREPLACE(Q35 , ""DAC(\d+_OUT\d+)|."" , ""$1 "") )"),"") | P35: =IFERROR(__xludf.DUMMYFUNCTION("TRIM(REGEXREPLACE(REGEXREPLACE(R35, "","", "" ""), ""(EVENTOUT|TRACECLK|TRACED.|SPI._[^ ]*|SAI._[^ ]*|ETH_[^ ]*|QUADSPI_[^ ]*|FMC_[^ ]*|UART._[^ ]*|FDCAN._[^ ]*|DFSDM._[^ ]*|OTG_[^ ]*|TIM\d+_[^ ]*)( |$)"", "" ""))"),"I2C1_SDA I2C4_SDA SDMMC1_CDIR SDMMC2_D5 I2C4_SMBA SDMMC1_D5 DCMI_D7 LCD_B7") -> I2C1_SDA I2C4_SDA SDMMC1_CDIR SDMMC2_D5 I2C4_SMBA SDMMC1_D5 DCMI_D7 LCD_B7 | R35: TIM17_CH1, TIM4_CH4,DFSDM1_DATIN7,I2C1_SDA,SPI2_NSS/I2S2_WS,I2C4_SDA,SDMMC1_CDIR,UART4_TX,FDCAN1_TX,SDMMC2_D5,I2C4_SMBA,SDMMC1_D5, DCMI_D7,LCD_B7, EVENTOUT
A36: 15 | B36: PC0 | D36: =IF(COUNTIF(ConnectorPins!$F$2:$F$999, B36) > 0, MATCH(B36, ConnectorPins!$F$2:$F$999, 0), IF(COUNTIF(ConnectorPins!$I$2:$I$999, B36) > 0, MATCH(B36, ConnectorPins!$I$2:$I$999, 0) + 35, "")) -> 67 | G36: =IFERROR(__xludf.DUMMYFUNCTION("TRIM(REGEXREPLACE(Q36 , ""ADC(\d+_(INN\d+|INP\d+)*)|."" , ""$1 "") )"),"123_INP10") -> 123_INP10 | I36: =IFERROR(__xludf.DUMMYFUNCTION("TRIM(REGEXREPLACE(R36 , ""SPI(._(MOSI|MISO|SCK))|."" , ""$1 "") )"),"") | J36: =IFERROR(__xludf.DUMMYFUNCTION("TRIM(REGEXREPLACE(R36 , ""FDCAN(._[\w_]+)|."" , ""$1 "") )"),"") | K36: =IFERROR(__xludf.DUMMYFUNCTION("TRIM(REGEXREPLACE(R36 , ""ETH_([\w_]+)|."" , ""$1 "") )"),"") | L36: =IFERROR(__xludf.DUMMYFUNCTION("TRIM(REGEXREPLACE(R36 , ""TIM(._\w+)|."" , ""$1 "") )"),"") | M36: =IFERROR(__xludf.DUMMYFUNCTION("TRIM(REGEXREPLACE(R36 , ""OTG_([\w_]+)|."" , ""$1 "") )"),"HS_ULPI_STP") -> HS_ULPI_STP | N36: =IFERROR(__xludf.DUMMYFUNCTION("TRIM(REGEXREPLACE(R36 , ""US?ART(._(TX|RX))|."" , ""$1 "") )"),"") | O36: =IFERROR(__xludf.DUMMYFUNCTION("TRIM(REGEXREPLACE(Q36 , ""DAC(\d+_OUT\d+)|."" , ""$1 "") )"),"") | P36: =IFERROR(__xludf.DUMMYFUNCTION("TRIM(REGEXREPLACE(REGEXREPLACE(R36, "","", "" ""), ""(EVENTOUT|TRACECLK|TRACED.|SPI._[^ ]*|SAI._[^ ]*|ETH_[^ ]*|QUADSPI_[^ ]*|FMC_[^ ]*|UART._[^ ]*|FDCAN._[^ ]*|DFSDM._[^ ]*|OTG_[^ ]*|TIM\d+_[^ ]*)( |$)"", "" ""))"),"LCD_R5") -> LCD_R5 | Q36: ADC123_INP10 | R36: DFSDM1_CKIN0,DFSDM1_DATIN4,SAI2_FS_B,OTG_HS_ULPI_STP,FMC_SDNWE, LCD_R5,EVENTOUT
A37: 16 | B37: PC1 | D37: =IF(COUNTIF(ConnectorPins!$F$2:$F$999, B37) > 0, MATCH(B37, ConnectorPins!$F$2:$F$999, 0), IF(COUNTIF(ConnectorPins!$I$2:$I$999, B37) > 0, MATCH(B37, ConnectorPins!$I$2:$I$999, 0) + 35, "")) -> 27 | E37: ETH_MDC | G37: =IFERROR(__xludf.DUMMYFUNCTION("TRIM(REGEXREPLACE(Q37 , ""ADC(\d+_(INN\d+|INP\d+)*)|."" , ""$1 "") )"),"123_INN10 123_INP11") -> 123_INN10 123_INP11 | I37: =IFERROR(__xludf.DUMMYFUNCTION("TRIM(REGEXREPLACE(R37 , ""SPI(._(MOSI|MISO|SCK))|."" , ""$1 "") )"),"2_MOSI") -> 2_MOSI | J37: =IFERROR(__xludf.DUMMYFUNCTION("TRIM(REGEXREPLACE(R37 , ""FDCAN(._[\w_]+)|."" , ""$1 "") )"),"") | K37: =IFERROR(__xludf.DUMMYFUNCTION("TRIM(REGEXREPLACE(R37 , ""ETH_([\w_]+)|."" , ""$1 "") )"),"MDC") -> MDC | L37: =IFERROR(__xludf.DUMMYFUNCTION("TRIM(REGEXREPLACE(R37 , ""TIM(._\w+)|."" , ""$1 "") )"),"") | M37: =IFERROR(__xludf.DUMMYFUNCTION("TRIM(REGEXREPLACE(R37 , ""OTG_([\w_]+)|."" , ""$1 "") )"),"") | N37: =IFERROR(__xludf.DUMMYFUNCTION("TRIM(REGEXREPLACE(R37 , ""US?ART(._(TX|RX))|."" , ""$1 "") )"),"") | O37: =IFERROR(__xludf.DUMMYFUNCTION("TRIM(REGEXREPLACE(Q37 , ""DAC(\d+_OUT\d+)|."" , ""$1 "") )"),"") | P37: =IFERROR(__xludf.DUMMYFUNCTION("TRIM(REGEXREPLACE(REGEXREPLACE(R37, "","", "" ""), ""(EVENTOUT|TRACECLK|TRACED.|SPI._[^ ]*|SAI._[^ ]*|ETH_[^ ]*|QUADSPI_[^ ]*|FMC_[^ ]*|UART._[^ ]*|FDCAN._[^ ]*|DFSDM._[^ ]*|OTG_[^ ]*|TIM\d+_[^ ]*)( |$)"", "" ""))"),"SDMMC2_CK MDIOS_MDC") -> SDMMC2_CK MDIOS_MDC | Q37: ADC123_INN10,ADC123_INP11,RTC_TAMP3/WKUP6 | R37: TRACED0, SAI1_D1,DFSDM1_DATIN0,DFSDM1_CKIN4,SPI2_MOSI/I2S2_SDO,SAI1_SD_A, SAI4_SD_A,SDMMC2_CK, SAI4_D1,ETH_MDC,MDIOS_MDC,EVENTOUT
A38: 78 | B38: PC10 | C38: SPI3_SCK | D38: =IF(COUNTIF(ConnectorPins!$F$2:$F$999, B38) > 0, MATCH(B38, ConnectorPins!$F$2:$F$999, 0), IF(COUNTIF(ConnectorPins!$I$2:$I$999, B38) > 0, MATCH(B38, ConnectorPins!$I$2:$I$999, 0), "")) -> 23 | E38: SPI3_SCK | F38: UART4_TX | G38: =IFERROR(__xludf.DUMMYFUNCTION("TRIM(REGEXREPLACE(Q38 , ""ADC(\d+_(INN\d+|INP\d+)*)|."" , ""$1 "") )"),"") | I38: =IFERROR(__xludf.DUMMYFUNCTION("TRIM(REGEXREPLACE(R38 , ""SPI(._(MOSI|MISO|SCK))|."" , ""$1 "") )"),"3_SCK") -> 3_SCK | J38: =IFERROR(__xludf.DUMMYFUNCTION("TRIM(REGEXREPLACE(R38 , ""FDCAN(._[\w_]+)|."" , ""$1 "") )"),"") | K38: =IFERROR(__xludf.DUMMYFUNCTION("TRIM(REGEXREPLACE(R38 , ""ETH_([\w_]+)|."" , ""$1 "") )"),"") | L38: =IFERROR(__xludf.DUMMYFUNCTION("TRIM(REGEXREPLACE(R38 , ""TIM(._\w+)|."" , ""$1 "") )"),"") | M38: =IFERROR(__xludf.DUMMYFUNCTION("TRIM(REGEXREPLACE(R38 , ""OTG_([\w_]+)|."" , ""$1 "") )"),"") | N38: =IFERROR(__xludf.DUMMYFUNCTION("TRIM(REGEXREPLACE(R38 , ""US?ART(._(TX|RX))|."" , ""$1 "") )"),"3_TX 4_TX") -> 3_TX 4_TX | O38: =IFERROR(__xludf.DUMMYFUNCTION("TRIM(REGEXREPLACE(Q38 , ""DAC(\d+_OUT\d+)|."" , ""$1 "") )"),"") | P38: =IFERROR(__xludf.DUMMYFUNCTION("TRIM(REGEXREPLACE(REGEXREPLACE(R38, "","", "" ""), ""(EVENTOUT|TRACECLK|TRACED.|SPI._[^ ]*|SAI._[^ ]*|ETH_[^ ]*|QUADSPI_[^ ]*|FMC_[^ ]*|UART._[^ ]*|FDCAN._[^ ]*|DFSDM._[^ ]*|OTG_[^ ]*|TIM\d+_[^ ]*)( |$)"", "" ""))"),"HRTIM_EEV1 USART3_TX SDMMC1_D2 DCMI_D8 LCD_R2") -> HRTIM_EEV1 USART3_TX SDMMC1_D2 DCMI_D8 LCD_R2 | R38: HRTIM_EEV1,DFSDM1_CKIN5,SPI3_SCK/I2S3_CK,USART3_TX,UART4_TX,QUADSPI_BK1_IO1,SDMMC1_D2, DCMI_D8,LCD_R2, EVENTOUT
